<?xml version="1.0" encoding="utf-8"?>
<!-- =================================================================================== -->
<!-- |    This document was autogenerated by xacro from dkitty.urdf.xacro              | -->
<!-- |    EDITING THIS FILE BY HAND IS NOT RECOMMENDED                                 | -->
<!-- =================================================================================== -->
<robot name="dkitty">
  <material name="black">
    <color rgba="0.15 0.15 0.15 1.0"/>
  </material>
  <material name="silver">
    <color rgba="0.78 0.78 0.78 1"/>
  </material>
  <material name="white">
    <color rgba="0.85 0.85 0.85 1"/>
  </material>
  <link name="base_link">
    <collision>
      <origin rpy="0 0 -1.5708" xyz="0 0 0"/>
      <geometry>
        <mesh filename="package://dkitty_description/meshes/bulkhead.stl"/>
      </geometry>
    </collision>
    <visual>
      <origin rpy="0 0 -1.5708" xyz="0 0 0"/>
      <geometry>
        <mesh filename="package://dkitty_description/meshes/bulkhead.stl"/>
      </geometry>
      <material name="white"/>
    </visual>
  </link>
  <link name="base_inertia">    
    </link>
  <joint name="base_link_to_base_inertia" type="fixed">
    <parent link="base_link"/>
    <child link="base_inertia"/>
    <origin rpy="0 0 0" xyz="0 0 0"/>
  </joint>
  <!-- <xacro:include filename="$(find dkitty_description)/urdf/accessories.urdf.xacro" /> -->
  <link name="lf_hip_debug_link"/>
  <link name="lf_hip_servo_link">
    <collision>
      <origin rpy="1.5708 0 0" xyz="0 -0.0102 0"/>
      <geometry>
        <mesh filename="package://dkitty_description/meshes/x430_dkitty_2.stl"/>
      </geometry>
    </collision>
    <visual>
      <origin rpy="1.5708 0 0" xyz="0 -0.0102 0"/>
      <geometry>
        <mesh filename="package://dkitty_description/meshes/x430_dkitty_2.stl"/>
      </geometry>
      <material name="black"/>
    </visual>
  </link>
  <link name="lf_hip_adapter_link">
    <collision>
      <origin rpy="3.1416 0 0" xyz="0 0 -0.0005"/>
      <geometry>
        <mesh filename="package://dkitty_description/meshes/fr12_h103_3.stl"/>
      </geometry>
    </collision>
    <visual>
      <origin rpy="3.1416 0 0" xyz="0 0 -0.0005"/>
      <geometry>
        <mesh filename="package://dkitty_description/meshes/fr12_h103_3.stl"/>
      </geometry>
      <material name="silver"/>
    </visual>
  </link>
  <link name="lf_upper_leg_servo_mount_link">
    <collision>
      <origin rpy="3.1416 0 1.5708" xyz="0 0 0"/>
      <geometry>
        <mesh filename="package://dkitty_description/meshes/fr12_h103_3.stl"/>
      </geometry>
    </collision>
    <visual>
      <origin rpy="3.1416 0 1.5708" xyz="0 0 0"/>
      <geometry>
        <mesh filename="package://dkitty_description/meshes/xh_clamping_small.stl"/>
      </geometry>
      <material name="black"/>
    </visual>
  </link>
  <link name="lf_upper_leg_servo_link">
    <collision>
      <origin rpy="0 0 1.5708" xyz="0 0 0.0102"/>
      <geometry>
        <mesh filename="package://dkitty_description/meshes/x430_dkitty_2.stl"/>
      </geometry>
    </collision>
    <visual>
      <origin rpy="0 0 1.5708" xyz="0 0 0.0102"/>
      <geometry>
        <mesh filename="package://dkitty_description/meshes/x430_dkitty_2.stl"/>
      </geometry>
      <material name="black"/>
    </visual>
  </link>
  <link name="lf_upper_leg_adapter_link">
    <collision>
      <origin rpy="3.1416 0 1.5708" xyz="0 0 -0.0005"/>
      <geometry>
        <mesh filename="package://dkitty_description/meshes/fr12_h103_3.stl"/>
      </geometry>
    </collision>
    <visual>
      <origin rpy="3.1416 0 1.5708" xyz="0 0 -0.0005"/>
      <geometry>
        <mesh filename="package://dkitty_description/meshes/fr12_h103_3.stl"/>
      </geometry>
      <material name="silver"/>
    </visual>
  </link>
  <link name="lf_lower_leg_servo_mount_link">
    <collision>
      <origin rpy="3.1416 0 1.5708" xyz="0 0 0"/>
      <geometry>
        <mesh filename="package://dkitty_description/meshes/fr12_h103_3.stl"/>
      </geometry>
    </collision>
    <visual>
      <origin rpy="3.1416 0 1.5708" xyz="0 0 0"/>
      <geometry>
        <mesh filename="package://dkitty_description/meshes/xh_clamping_small.stl"/>
      </geometry>
      <material name="black"/>
    </visual>
  </link>
  <link name="lf_lower_leg_servo_link">
    <collision>
      <origin rpy="0 0 1.5708" xyz="0 0 0.0102"/>
      <geometry>
        <mesh filename="package://dkitty_description/meshes/x430_dkitty_2.stl"/>
      </geometry>
    </collision>
    <visual>
      <origin rpy="0 0 1.5708" xyz="0 0 0.0102"/>
      <geometry>
        <mesh filename="package://dkitty_description/meshes/x430_dkitty_2.stl"/>
      </geometry>
      <material name="black"/>
    </visual>
  </link>
  <link name="lf_lower_leg_adapter_link">
    <collision>
      <origin rpy="3.1416 0 1.5708" xyz="0 0 -0.0005"/>
      <geometry>
        <mesh filename="package://dkitty_description/meshes/fr12_h103_3.stl"/>
      </geometry>
    </collision>
    <visual>
      <origin rpy="3.1416 0 1.5708" xyz="0 0 -0.0005"/>
      <geometry>
        <mesh filename="package://dkitty_description/meshes/fr12_h103_3.stl"/>
      </geometry>
      <material name="silver"/>
    </visual>
  </link>
  <link name="lf_foot_link">
    <collision>
      <origin rpy="3.1416 0 1.5708" xyz="0 0 0.0538"/>
      <geometry>
        <mesh filename="package://dkitty_description/meshes/xh_finger_tip.stl"/>
      </geometry>
    </collision>
    <visual>
      <origin rpy="3.1416 0 1.5708" xyz="0 0 0.0538"/>
      <geometry>
        <mesh filename="package://dkitty_description/meshes/xh_finger_tip.stl"/>
      </geometry>
      <material name="black"/>
    </visual>
  </link>
  <joint name="lf_debug_joint" type="fixed">
    <parent link="base_link"/>
    <child link="lf_hip_debug_link"/>
    <origin rpy="0 0 0" xyz="0.1212 0.0903 0"/>
  </joint>
  <joint name="lf_hip_joint" type="fixed">
    <parent link="base_link"/>
    <child link="lf_hip_servo_link"/>
    <origin rpy="0 0 0" xyz="0.1212 0.0903 0"/>
  </joint>
  <joint name="lf_hip_adapter_joint" type="revolute">
    <axis xyz="1 0 0"/>
    <limit effort="25" lower="-3.14159265359" upper="3.14159265359" velocity="1.5"/>
    <parent link="lf_hip_servo_link"/>
    <child link="lf_hip_adapter_link"/>
    <origin rpy="0 0 0" xyz="0 0 0"/>
  </joint>
  <joint name="lf_upper_leg_servo_mount_joint" type="fixed">
    <parent link="lf_hip_adapter_link"/>
    <child link="lf_upper_leg_servo_mount_link"/>
    <origin rpy="0 0 0" xyz="0 0 -0.055"/>
  </joint>
  <joint name="lf_upper_leg_joint" type="fixed">
    <parent link="lf_upper_leg_servo_mount_link"/>
    <child link="lf_upper_leg_servo_link"/>
    <origin rpy="0 0 0" xyz="0 0 -0.0405"/>
  </joint>
  <joint name="lf_upper_leg_adapter_joint" type="revolute">
    <axis xyz="0 1 0"/>
    <limit effort="25" lower="-3.14159265359" upper="3.14159265359" velocity="1.5"/>
    <parent link="lf_upper_leg_servo_link"/>
    <child link="lf_upper_leg_adapter_link"/>
    <origin rpy="0 0 0" xyz="0 0 0"/>
  </joint>
  <joint name="lf_lower_leg_servo_mount_joint" type="fixed">
    <parent link="lf_upper_leg_adapter_link"/>
    <child link="lf_lower_leg_servo_mount_link"/>
    <origin rpy="0 0 0" xyz="0 0 -0.055"/>
  </joint>
  <joint name="lf_lower_leg_joint" type="fixed">
    <parent link="lf_lower_leg_servo_mount_link"/>
    <child link="lf_lower_leg_servo_link"/>
    <origin rpy="0 0 0" xyz="0 0 -0.0405"/>
  </joint>
  <joint name="lf_lower_leg_adapter_joint" type="revolute">
    <axis xyz="0 1 0"/>
    <limit effort="25" lower="-3.14159265359" upper="3.14159265359" velocity="1.5"/>
    <parent link="lf_lower_leg_servo_link"/>
    <child link="lf_lower_leg_adapter_link"/>
    <origin rpy="0 0 0" xyz="0 0 0"/>
  </joint>
  <joint name="lf_foot_joint" type="fixed">
    <parent link="lf_lower_leg_adapter_link"/>
    <child link="lf_foot_link"/>
    <origin rpy="0 0 0" xyz="0 0 -0.10885"/>
  </joint>
  <transmission name="lf_hip_joint_trans">
    <type>transmission_interface/SimpleTransmission</type>
    <joint name="lf_hip_joint">
      <hardwareInterface>hardware_interface/EffortJointInterface</hardwareInterface>
    </joint>
    <actuator name="lf_hip_joint_motor">
      <hardwareInterface>hardware_interface/EffortJointInterface</hardwareInterface>
      <mechanicalReduction>1</mechanicalReduction>
    </actuator>
  </transmission>
  <transmission name="lf_upper_leg_joint_trans">
    <type>transmission_interface/SimpleTransmission</type>
    <joint name="lf_upper_leg_joint">
      <hardwareInterface>hardware_interface/EffortJointInterface</hardwareInterface>
    </joint>
    <actuator name="lf_upper_leg_joint_motor">
      <hardwareInterface>hardware_interface/EffortJointInterface</hardwareInterface>
      <mechanicalReduction>1</mechanicalReduction>
    </actuator>
  </transmission>
  <transmission name="lf_lower_leg_joint_trans">
    <type>transmission_interface/SimpleTransmission</type>
    <joint name="lf_lower_leg_joint">
      <hardwareInterface>hardware_interface/EffortJointInterface</hardwareInterface>
    </joint>
    <actuator name="lf_lower_joint_motor">
      <hardwareInterface>hardware_interface/EffortJointInterface</hardwareInterface>
      <mechanicalReduction>1</mechanicalReduction>
    </actuator>
  </transmission>
  <link name="lh_hip_debug_link"/>
  <link name="lh_hip_servo_link">
    <collision>
      <origin rpy="1.5708 3.1416 0" xyz="0 -0.0102 0"/>
      <geometry>
        <mesh filename="package://dkitty_description/meshes/x430_dkitty_2.stl"/>
      </geometry>
    </collision>
    <visual>
      <origin rpy="1.5708 3.1416 0" xyz="0 -0.0102 0"/>
      <geometry>
        <mesh filename="package://dkitty_description/meshes/x430_dkitty_2.stl"/>
      </geometry>
      <material name="black"/>
    </visual>
  </link>
  <link name="lh_hip_adapter_link">
    <collision>
      <origin rpy="3.1416 0 0" xyz="0 0 -0.0005"/>
      <geometry>
        <mesh filename="package://dkitty_description/meshes/fr12_h103_3.stl"/>
      </geometry>
    </collision>
    <visual>
      <origin rpy="3.1416 0 0" xyz="0 0 -0.0005"/>
      <geometry>
        <mesh filename="package://dkitty_description/meshes/fr12_h103_3.stl"/>
      </geometry>
      <material name="silver"/>
    </visual>
  </link>
  <link name="lh_upper_leg_servo_mount_link">
    <collision>
      <origin rpy="3.1416 0 1.5708" xyz="0 0 0"/>
      <geometry>
        <mesh filename="package://dkitty_description/meshes/fr12_h103_3.stl"/>
      </geometry>
    </collision>
    <visual>
      <origin rpy="3.1416 0 1.5708" xyz="0 0 0"/>
      <geometry>
        <mesh filename="package://dkitty_description/meshes/xh_clamping_small.stl"/>
      </geometry>
      <material name="black"/>
    </visual>
  </link>
  <link name="lh_upper_leg_servo_link">
    <collision>
      <origin rpy="0 0 1.5708" xyz="0 0 0.0102"/>
      <geometry>
        <mesh filename="package://dkitty_description/meshes/x430_dkitty_2.stl"/>
      </geometry>
    </collision>
    <visual>
      <origin rpy="0 0 1.5708" xyz="0 0 0.0102"/>
      <geometry>
        <mesh filename="package://dkitty_description/meshes/x430_dkitty_2.stl"/>
      </geometry>
      <material name="black"/>
    </visual>
  </link>
  <link name="lh_upper_leg_adapter_link">
    <collision>
      <origin rpy="3.1416 0 1.5708" xyz="0 0 -0.0005"/>
      <geometry>
        <mesh filename="package://dkitty_description/meshes/fr12_h103_3.stl"/>
      </geometry>
    </collision>
    <visual>
      <origin rpy="3.1416 0 1.5708" xyz="0 0 -0.0005"/>
      <geometry>
        <mesh filename="package://dkitty_description/meshes/fr12_h103_3.stl"/>
      </geometry>
      <material name="silver"/>
    </visual>
  </link>
  <link name="lh_lower_leg_servo_mount_link">
    <collision>
      <origin rpy="3.1416 0 1.5708" xyz="0 0 0"/>
      <geometry>
        <mesh filename="package://dkitty_description/meshes/fr12_h103_3.stl"/>
      </geometry>
    </collision>
    <visual>
      <origin rpy="3.1416 0 1.5708" xyz="0 0 0"/>
      <geometry>
        <mesh filename="package://dkitty_description/meshes/xh_clamping_small.stl"/>
      </geometry>
      <material name="black"/>
    </visual>
  </link>
  <link name="lh_lower_leg_servo_link">
    <collision>
      <origin rpy="0 0 1.5708" xyz="0 0 0.0102"/>
      <geometry>
        <mesh filename="package://dkitty_description/meshes/x430_dkitty_2.stl"/>
      </geometry>
    </collision>
    <visual>
      <origin rpy="0 0 1.5708" xyz="0 0 0.0102"/>
      <geometry>
        <mesh filename="package://dkitty_description/meshes/x430_dkitty_2.stl"/>
      </geometry>
      <material name="black"/>
    </visual>
  </link>
  <link name="lh_lower_leg_adapter_link">
    <collision>
      <origin rpy="3.1416 0 1.5708" xyz="0 0 -0.0005"/>
      <geometry>
        <mesh filename="package://dkitty_description/meshes/fr12_h103_3.stl"/>
      </geometry>
    </collision>
    <visual>
      <origin rpy="3.1416 0 1.5708" xyz="0 0 -0.0005"/>
      <geometry>
        <mesh filename="package://dkitty_description/meshes/fr12_h103_3.stl"/>
      </geometry>
      <material name="silver"/>
    </visual>
  </link>
  <link name="lh_foot_link">
    <collision>
      <origin rpy="3.1416 0 1.5708" xyz="0 0 0.0538"/>
      <geometry>
        <mesh filename="package://dkitty_description/meshes/xh_finger_tip.stl"/>
      </geometry>
    </collision>
    <visual>
      <origin rpy="3.1416 0 1.5708" xyz="0 0 0.0538"/>
      <geometry>
        <mesh filename="package://dkitty_description/meshes/xh_finger_tip.stl"/>
      </geometry>
      <material name="black"/>
    </visual>
  </link>
  <joint name="lh_debug_joint" type="fixed">
    <parent link="base_link"/>
    <child link="lh_hip_debug_link"/>
    <origin rpy="0 0 0" xyz="-0.1212 0.0903 0"/>
  </joint>
  <joint name="lh_hip_joint" type="fixed">
    <parent link="base_link"/>
    <child link="lh_hip_servo_link"/>
    <origin rpy="0 0 0" xyz="-0.1212 0.0903 0"/>
  </joint>
  <joint name="lh_hip_adapter_joint" type="revolute">
    <axis xyz="1 0 0"/>
    <limit effort="25" lower="-3.14159265359" upper="3.14159265359" velocity="1.5"/>
    <parent link="lh_hip_servo_link"/>
    <child link="lh_hip_adapter_link"/>
    <origin rpy="0 0 0" xyz="0 0 0"/>
  </joint>
  <joint name="lh_upper_leg_servo_mount_joint" type="fixed">
    <parent link="lh_hip_adapter_link"/>
    <child link="lh_upper_leg_servo_mount_link"/>
    <origin rpy="0 0 0" xyz="0 0 -0.055"/>
  </joint>
  <joint name="lh_upper_leg_joint" type="fixed">
    <parent link="lh_upper_leg_servo_mount_link"/>
    <child link="lh_upper_leg_servo_link"/>
    <origin rpy="0 0 0" xyz="0 0 -0.0405"/>
  </joint>
  <joint name="lh_upper_leg_adapter_joint" type="revolute">
    <axis xyz="0 1 0"/>
    <limit effort="25" lower="-3.14159265359" upper="3.14159265359" velocity="1.5"/>
    <parent link="lh_upper_leg_servo_link"/>
    <child link="lh_upper_leg_adapter_link"/>
    <origin rpy="0 0 0" xyz="0 0 0"/>
  </joint>
  <joint name="lh_lower_leg_servo_mount_joint" type="fixed">
    <parent link="lh_upper_leg_adapter_link"/>
    <child link="lh_lower_leg_servo_mount_link"/>
    <origin rpy="0 0 0" xyz="0 0 -0.055"/>
  </joint>
  <joint name="lh_lower_leg_joint" type="fixed">
    <parent link="lh_lower_leg_servo_mount_link"/>
    <child link="lh_lower_leg_servo_link"/>
    <origin rpy="0 0 0" xyz="0 0 -0.0405"/>
  </joint>
  <joint name="lh_lower_leg_adapter_joint" type="revolute">
    <axis xyz="0 1 0"/>
    <limit effort="25" lower="-3.14159265359" upper="3.14159265359" velocity="1.5"/>
    <parent link="lh_lower_leg_servo_link"/>
    <child link="lh_lower_leg_adapter_link"/>
    <origin rpy="0 0 0" xyz="0 0 0"/>
  </joint>
  <joint name="lh_foot_joint" type="fixed">
    <parent link="lh_lower_leg_adapter_link"/>
    <child link="lh_foot_link"/>
    <origin rpy="0 0 0" xyz="0 0 -0.10885"/>
  </joint>
  <transmission name="lh_hip_joint_trans">
    <type>transmission_interface/SimpleTransmission</type>
    <joint name="lh_hip_joint">
      <hardwareInterface>hardware_interface/EffortJointInterface</hardwareInterface>
    </joint>
    <actuator name="lh_hip_joint_motor">
      <hardwareInterface>hardware_interface/EffortJointInterface</hardwareInterface>
      <mechanicalReduction>1</mechanicalReduction>
    </actuator>
  </transmission>
  <transmission name="lh_upper_leg_joint_trans">
    <type>transmission_interface/SimpleTransmission</type>
    <joint name="lh_upper_leg_joint">
      <hardwareInterface>hardware_interface/EffortJointInterface</hardwareInterface>
    </joint>
    <actuator name="lh_upper_leg_joint_motor">
      <hardwareInterface>hardware_interface/EffortJointInterface</hardwareInterface>
      <mechanicalReduction>1</mechanicalReduction>
    </actuator>
  </transmission>
  <transmission name="lh_lower_leg_joint_trans">
    <type>transmission_interface/SimpleTransmission</type>
    <joint name="lh_lower_leg_joint">
      <hardwareInterface>hardware_interface/EffortJointInterface</hardwareInterface>
    </joint>
    <actuator name="lh_lower_joint_motor">
      <hardwareInterface>hardware_interface/EffortJointInterface</hardwareInterface>
      <mechanicalReduction>1</mechanicalReduction>
    </actuator>
  </transmission>
  <link name="rf_hip_debug_link"/>
  <link name="rf_hip_servo_link">
    <collision>
      <origin rpy="-1.5708 0 0" xyz="0 0.0102 0"/>
      <geometry>
        <mesh filename="package://dkitty_description/meshes/x430_dkitty_2.stl"/>
      </geometry>
    </collision>
    <visual>
      <origin rpy="-1.5708 0 0" xyz="0 0.0102 0"/>
      <geometry>
        <mesh filename="package://dkitty_description/meshes/x430_dkitty_2.stl"/>
      </geometry>
      <material name="black"/>
    </visual>
  </link>
  <link name="rf_hip_adapter_link">
    <collision>
      <origin rpy="3.1416 0 0" xyz="0 0 -0.0005"/>
      <geometry>
        <mesh filename="package://dkitty_description/meshes/fr12_h103_3.stl"/>
      </geometry>
    </collision>
    <visual>
      <origin rpy="3.1416 0 0" xyz="0 0 -0.0005"/>
      <geometry>
        <mesh filename="package://dkitty_description/meshes/fr12_h103_3.stl"/>
      </geometry>
      <material name="silver"/>
    </visual>
  </link>
  <link name="rf_upper_leg_servo_mount_link">
    <collision>
      <origin rpy="3.1416 0 -1.5708" xyz="0 0 0"/>
      <geometry>
        <mesh filename="package://dkitty_description/meshes/fr12_h103_3.stl"/>
      </geometry>
    </collision>
    <visual>
      <origin rpy="3.1416 0 -1.5708" xyz="0 0 0"/>
      <geometry>
        <mesh filename="package://dkitty_description/meshes/xh_clamping_small.stl"/>
      </geometry>
      <material name="black"/>
    </visual>
  </link>
  <link name="rf_upper_leg_servo_link">
    <collision>
      <origin rpy="0 0 -1.5708" xyz="0 0 0.0102"/>
      <geometry>
        <mesh filename="package://dkitty_description/meshes/x430_dkitty_2.stl"/>
      </geometry>
    </collision>
    <visual>
      <origin rpy="0 0 -1.5708" xyz="0 0 0.0102"/>
      <geometry>
        <mesh filename="package://dkitty_description/meshes/x430_dkitty_2.stl"/>
      </geometry>
      <material name="black"/>
    </visual>
  </link>
  <link name="rf_upper_leg_adapter_link">
    <collision>
      <origin rpy="3.1416 0 1.5708" xyz="0 0 -0.0005"/>
      <geometry>
        <mesh filename="package://dkitty_description/meshes/fr12_h103_3.stl"/>
      </geometry>
    </collision>
    <visual>
      <origin rpy="3.1416 0 1.5708" xyz="0 0 -0.0005"/>
      <geometry>
        <mesh filename="package://dkitty_description/meshes/fr12_h103_3.stl"/>
      </geometry>
      <material name="silver"/>
    </visual>
  </link>
  <link name="rf_lower_leg_servo_mount_link">
    <collision>
      <origin rpy="3.1416 0 -1.5708" xyz="0 0 0"/>
      <geometry>
        <mesh filename="package://dkitty_description/meshes/fr12_h103_3.stl"/>
      </geometry>
    </collision>
    <visual>
      <origin rpy="3.1416 0 -1.5708" xyz="0 0 0"/>
      <geometry>
        <mesh filename="package://dkitty_description/meshes/xh_clamping_small.stl"/>
      </geometry>
      <material name="black"/>
    </visual>
  </link>
  <link name="rf_lower_leg_servo_link">
    <collision>
      <origin rpy="0 0 -1.5708" xyz="0 0 0.0102"/>
      <geometry>
        <mesh filename="package://dkitty_description/meshes/x430_dkitty_2.stl"/>
      </geometry>
    </collision>
    <visual>
      <origin rpy="0 0 -1.5708" xyz="0 0 0.0102"/>
      <geometry>
        <mesh filename="package://dkitty_description/meshes/x430_dkitty_2.stl"/>
      </geometry>
      <material name="black"/>
    </visual>
  </link>
  <link name="rf_lower_leg_adapter_link">
    <collision>
      <origin rpy="3.1416 0 1.5708" xyz="0 0 -0.0005"/>
      <geometry>
        <mesh filename="package://dkitty_description/meshes/fr12_h103_3.stl"/>
      </geometry>
    </collision>
    <visual>
      <origin rpy="3.1416 0 1.5708" xyz="0 0 -0.0005"/>
      <geometry>
        <mesh filename="package://dkitty_description/meshes/fr12_h103_3.stl"/>
      </geometry>
      <material name="silver"/>
    </visual>
  </link>
  <link name="rf_foot_link">
    <collision>
      <origin rpy="3.1416 0 1.5708" xyz="0 0 0.0538"/>
      <geometry>
        <mesh filename="package://dkitty_description/meshes/xh_finger_tip.stl"/>
      </geometry>
    </collision>
    <visual>
      <origin rpy="3.1416 0 1.5708" xyz="0 0 0.0538"/>
      <geometry>
        <mesh filename="package://dkitty_description/meshes/xh_finger_tip.stl"/>
      </geometry>
      <material name="black"/>
    </visual>
  </link>
  <joint name="rf_debug_joint" type="fixed">
    <parent link="base_link"/>
    <child link="rf_hip_debug_link"/>
    <origin rpy="0 0 0" xyz="0.1212 -0.0903 0"/>
  </joint>
  <joint name="rf_hip_joint" type="fixed">
    <parent link="base_link"/>
    <child link="rf_hip_servo_link"/>
    <origin rpy="0 0 0" xyz="0.1212 -0.0903 0"/>
  </joint>
  <joint name="rf_hip_adapter_joint" type="revolute">
    <axis xyz="1 0 0"/>
    <limit effort="25" lower="-3.14159265359" upper="3.14159265359" velocity="1.5"/>
    <parent link="rf_hip_servo_link"/>
    <child link="rf_hip_adapter_link"/>
    <origin rpy="0 0 0" xyz="0 0 0"/>
  </joint>
  <joint name="rf_upper_leg_servo_mount_joint" type="fixed">
    <parent link="rf_hip_adapter_link"/>
    <child link="rf_upper_leg_servo_mount_link"/>
    <origin rpy="0 0 0" xyz="0 0 -0.055"/>
  </joint>
  <joint name="rf_upper_leg_joint" type="fixed">
    <parent link="rf_upper_leg_servo_mount_link"/>
    <child link="rf_upper_leg_servo_link"/>
    <origin rpy="0 0 0" xyz="0 0 -0.0405"/>
  </joint>
  <joint name="rf_upper_leg_adapter_joint" type="revolute">
    <axis xyz="0 1 0"/>
    <limit effort="25" lower="-3.14159265359" upper="3.14159265359" velocity="1.5"/>
    <parent link="rf_upper_leg_servo_link"/>
    <child link="rf_upper_leg_adapter_link"/>
    <origin rpy="0 0 0" xyz="0 0 0"/>
  </joint>
  <joint name="rf_lower_leg_servo_mount_joint" type="fixed">
    <parent link="rf_upper_leg_adapter_link"/>
    <child link="rf_lower_leg_servo_mount_link"/>
    <origin rpy="0 0 0" xyz="0 0 -0.055"/>
  </joint>
  <joint name="rf_lower_leg_joint" type="fixed">
    <parent link="rf_lower_leg_servo_mount_link"/>
    <child link="rf_lower_leg_servo_link"/>
    <origin rpy="0 0 0" xyz="0 0 -0.0405"/>
  </joint>
  <joint name="rf_lower_leg_adapter_joint" type="revolute">
    <axis xyz="0 1 0"/>
    <limit effort="25" lower="-3.14159265359" upper="3.14159265359" velocity="1.5"/>
    <parent link="rf_lower_leg_servo_link"/>
    <child link="rf_lower_leg_adapter_link"/>
    <origin rpy="0 0 0" xyz="0 0 0"/>
  </joint>
  <joint name="rf_foot_joint" type="fixed">
    <parent link="rf_lower_leg_adapter_link"/>
    <child link="rf_foot_link"/>
    <origin rpy="0 0 0" xyz="0 0 -0.10885"/>
  </joint>
  <transmission name="rf_hip_joint_trans">
    <type>transmission_interface/SimpleTransmission</type>
    <joint name="rf_hip_joint">
      <hardwareInterface>hardware_interface/EffortJointInterface</hardwareInterface>
    </joint>
    <actuator name="rf_hip_joint_motor">
      <hardwareInterface>hardware_interface/EffortJointInterface</hardwareInterface>
      <mechanicalReduction>1</mechanicalReduction>
    </actuator>
  </transmission>
  <transmission name="rf_upper_leg_joint_trans">
    <type>transmission_interface/SimpleTransmission</type>
    <joint name="rf_upper_leg_joint">
      <hardwareInterface>hardware_interface/EffortJointInterface</hardwareInterface>
    </joint>
    <actuator name="rf_upper_leg_joint_motor">
      <hardwareInterface>hardware_interface/EffortJointInterface</hardwareInterface>
      <mechanicalReduction>1</mechanicalReduction>
    </actuator>
  </transmission>
  <transmission name="rf_lower_leg_joint_trans">
    <type>transmission_interface/SimpleTransmission</type>
    <joint name="rf_lower_leg_joint">
      <hardwareInterface>hardware_interface/EffortJointInterface</hardwareInterface>
    </joint>
    <actuator name="rf_lower_joint_motor">
      <hardwareInterface>hardware_interface/EffortJointInterface</hardwareInterface>
      <mechanicalReduction>1</mechanicalReduction>
    </actuator>
  </transmission>
  <link name="rh_hip_debug_link"/>
  <link name="rh_hip_servo_link">
    <collision>
      <origin rpy="-1.5708 3.1416 0" xyz="0 0.0102 0"/>
      <geometry>
        <mesh filename="package://dkitty_description/meshes/x430_dkitty_2.stl"/>
      </geometry>
    </collision>
    <visual>
      <origin rpy="-1.5708 3.1416 0" xyz="0 0.0102 0"/>
      <geometry>
        <mesh filename="package://dkitty_description/meshes/x430_dkitty_2.stl"/>
      </geometry>
      <material name="black"/>
    </visual>
  </link>
  <link name="rh_hip_adapter_link">
    <collision>
      <origin rpy="3.1416 0 0" xyz="0 0 -0.0005"/>
      <geometry>
        <mesh filename="package://dkitty_description/meshes/fr12_h103_3.stl"/>
      </geometry>
    </collision>
    <visual>
      <origin rpy="3.1416 0 0" xyz="0 0 -0.0005"/>
      <geometry>
        <mesh filename="package://dkitty_description/meshes/fr12_h103_3.stl"/>
      </geometry>
      <material name="silver"/>
    </visual>
  </link>
  <link name="rh_upper_leg_servo_mount_link">
    <collision>
      <origin rpy="3.1416 0 -1.5708" xyz="0 0 0"/>
      <geometry>
        <mesh filename="package://dkitty_description/meshes/fr12_h103_3.stl"/>
      </geometry>
    </collision>
    <visual>
      <origin rpy="3.1416 0 -1.5708" xyz="0 0 0"/>
      <geometry>
        <mesh filename="package://dkitty_description/meshes/xh_clamping_small.stl"/>
      </geometry>
      <material name="black"/>
    </visual>
  </link>
  <link name="rh_upper_leg_servo_link">
    <collision>
      <origin rpy="0 0 -1.5708" xyz="0 0 0.0102"/>
      <geometry>
        <mesh filename="package://dkitty_description/meshes/x430_dkitty_2.stl"/>
      </geometry>
    </collision>
    <visual>
      <origin rpy="0 0 -1.5708" xyz="0 0 0.0102"/>
      <geometry>
        <mesh filename="package://dkitty_description/meshes/x430_dkitty_2.stl"/>
      </geometry>
      <material name="black"/>
    </visual>
  </link>
  <link name="rh_upper_leg_adapter_link">
    <collision>
      <origin rpy="3.1416 0 1.5708" xyz="0 0 -0.0005"/>
      <geometry>
        <mesh filename="package://dkitty_description/meshes/fr12_h103_3.stl"/>
      </geometry>
    </collision>
    <visual>
      <origin rpy="3.1416 0 1.5708" xyz="0 0 -0.0005"/>
      <geometry>
        <mesh filename="package://dkitty_description/meshes/fr12_h103_3.stl"/>
      </geometry>
      <material name="silver"/>
    </visual>
  </link>
  <link name="rh_lower_leg_servo_mount_link">
    <collision>
      <origin rpy="3.1416 0 -1.5708" xyz="0 0 0"/>
      <geometry>
        <mesh filename="package://dkitty_description/meshes/fr12_h103_3.stl"/>
      </geometry>
    </collision>
    <visual>
      <origin rpy="3.1416 0 -1.5708" xyz="0 0 0"/>
      <geometry>
        <mesh filename="package://dkitty_description/meshes/xh_clamping_small.stl"/>
      </geometry>
      <material name="black"/>
    </visual>
  </link>
  <link name="rh_lower_leg_servo_link">
    <collision>
      <origin rpy="0 0 -1.5708" xyz="0 0 0.0102"/>
      <geometry>
        <mesh filename="package://dkitty_description/meshes/x430_dkitty_2.stl"/>
      </geometry>
    </collision>
    <visual>
      <origin rpy="0 0 -1.5708" xyz="0 0 0.0102"/>
      <geometry>
        <mesh filename="package://dkitty_description/meshes/x430_dkitty_2.stl"/>
      </geometry>
      <material name="black"/>
    </visual>
  </link>
  <link name="rh_lower_leg_adapter_link">
    <collision>
      <origin rpy="3.1416 0 1.5708" xyz="0 0 -0.0005"/>
      <geometry>
        <mesh filename="package://dkitty_description/meshes/fr12_h103_3.stl"/>
      </geometry>
    </collision>
    <visual>
      <origin rpy="3.1416 0 1.5708" xyz="0 0 -0.0005"/>
      <geometry>
        <mesh filename="package://dkitty_description/meshes/fr12_h103_3.stl"/>
      </geometry>
      <material name="silver"/>
    </visual>
  </link>
  <link name="rh_foot_link">
    <collision>
      <origin rpy="3.1416 0 1.5708" xyz="0 0 0.0538"/>
      <geometry>
        <mesh filename="package://dkitty_description/meshes/xh_finger_tip.stl"/>
      </geometry>
    </collision>
    <visual>
      <origin rpy="3.1416 0 1.5708" xyz="0 0 0.0538"/>
      <geometry>
        <mesh filename="package://dkitty_description/meshes/xh_finger_tip.stl"/>
      </geometry>
      <material name="black"/>
    </visual>
  </link>
  <joint name="rh_debug_joint" type="fixed">
    <parent link="base_link"/>
    <child link="rh_hip_debug_link"/>
    <origin rpy="0 0 0" xyz="-0.1212 -0.0903 0"/>
  </joint>
  <joint name="rh_hip_joint" type="fixed">
    <parent link="base_link"/>
    <child link="rh_hip_servo_link"/>
    <origin rpy="0 0 0" xyz="-0.1212 -0.0903 0"/>
  </joint>
  <joint name="rh_hip_adapter_joint" type="revolute">
    <axis xyz="1 0 0"/>
    <limit effort="25" lower="-3.14159265359" upper="3.14159265359" velocity="1.5"/>
    <parent link="rh_hip_servo_link"/>
    <child link="rh_hip_adapter_link"/>
    <origin rpy="0 0 0" xyz="0 0 0"/>
  </joint>
  <joint name="rh_upper_leg_servo_mount_joint" type="fixed">
    <parent link="rh_hip_adapter_link"/>
    <child link="rh_upper_leg_servo_mount_link"/>
    <origin rpy="0 0 0" xyz="0 0 -0.055"/>
  </joint>
  <joint name="rh_upper_leg_joint" type="fixed">
    <parent link="rh_upper_leg_servo_mount_link"/>
    <child link="rh_upper_leg_servo_link"/>
    <origin rpy="0 0 0" xyz="0 0 -0.0405"/>
  </joint>
  <joint name="rh_upper_leg_adapter_joint" type="revolute">
    <axis xyz="0 1 0"/>
    <limit effort="25" lower="-3.14159265359" upper="3.14159265359" velocity="1.5"/>
    <parent link="rh_upper_leg_servo_link"/>
    <child link="rh_upper_leg_adapter_link"/>
    <origin rpy="0 0 0" xyz="0 0 0"/>
  </joint>
  <joint name="rh_lower_leg_servo_mount_joint" type="fixed">
    <parent link="rh_upper_leg_adapter_link"/>
    <child link="rh_lower_leg_servo_mount_link"/>
    <origin rpy="0 0 0" xyz="0 0 -0.055"/>
  </joint>
  <joint name="rh_lower_leg_joint" type="fixed">
    <parent link="rh_lower_leg_servo_mount_link"/>
    <child link="rh_lower_leg_servo_link"/>
    <origin rpy="0 0 0" xyz="0 0 -0.0405"/>
  </joint>
  <joint name="rh_lower_leg_adapter_joint" type="revolute">
    <axis xyz="0 1 0"/>
    <limit effort="25" lower="-3.14159265359" upper="3.14159265359" velocity="1.5"/>
    <parent link="rh_lower_leg_servo_link"/>
    <child link="rh_lower_leg_adapter_link"/>
    <origin rpy="0 0 0" xyz="0 0 0"/>
  </joint>
  <joint name="rh_foot_joint" type="fixed">
    <parent link="rh_lower_leg_adapter_link"/>
    <child link="rh_foot_link"/>
    <origin rpy="0 0 0" xyz="0 0 -0.10885"/>
  </joint>
  <transmission name="rh_hip_joint_trans">
    <type>transmission_interface/SimpleTransmission</type>
    <joint name="rh_hip_joint">
      <hardwareInterface>hardware_interface/EffortJointInterface</hardwareInterface>
    </joint>
    <actuator name="rh_hip_joint_motor">
      <hardwareInterface>hardware_interface/EffortJointInterface</hardwareInterface>
      <mechanicalReduction>1</mechanicalReduction>
    </actuator>
  </transmission>
  <transmission name="rh_upper_leg_joint_trans">
    <type>transmission_interface/SimpleTransmission</type>
    <joint name="rh_upper_leg_joint">
      <hardwareInterface>hardware_interface/EffortJointInterface</hardwareInterface>
    </joint>
    <actuator name="rh_upper_leg_joint_motor">
      <hardwareInterface>hardware_interface/EffortJointInterface</hardwareInterface>
      <mechanicalReduction>1</mechanicalReduction>
    </actuator>
  </transmission>
  <transmission name="rh_lower_leg_joint_trans">
    <type>transmission_interface/SimpleTransmission</type>
    <joint name="rh_lower_leg_joint">
      <hardwareInterface>hardware_interface/EffortJointInterface</hardwareInterface>
    </joint>
    <actuator name="rh_lower_joint_motor">
      <hardwareInterface>hardware_interface/EffortJointInterface</hardwareInterface>
      <mechanicalReduction>1</mechanicalReduction>
    </actuator>
  </transmission>
  <gazebo>
    <plugin filename="libgazebo_ros_p3d.so" name="p3d_base_controller">
      <alwaysOn>true</alwaysOn>
      <updateRate>10.0</updateRate>
      <bodyName>base_link</bodyName>
      <topicName>odom/ground_truth</topicName>
      <gaussianNoise>0.01</gaussianNoise>
      <frameName>world</frameName>
      <xyzOffsets>0 0 0</xyzOffsets>
      <rpyOffsets>0 0 0</rpyOffsets>
    </plugin>
  </gazebo>
  <gazebo>
    <plugin filename="libgazebo_ros_control.so" name="gazebo_ros_control">
      <legacyModeNS>true</legacyModeNS>
    </plugin>
  </gazebo>
</robot>

