<?xml version="1.0" encoding="utf-8"?>
<!-- This URDF was automatically created by SolidWorks to URDF Exporter! Originally created by Stephen Brawner (brawner@gmail.com) 
     Commit Version: 1.6.0-1-g15f4949  Build Version: 1.6.7594.29634
     For more information, please see http://wiki.ros.org/sw_urdf_exporter -->
<robot
  name="stanford_pupper">
  <gazebo>
    <plugin filename="libgazebo_ros_control.so" name="gazebo_ros_control">
    <legacyModeNS>true</legacyModeNS>
    </plugin>
  </gazebo>
  <link
    name="base_link">
     <inertial>
      <origin
        xyz="-0.0185439793772625 0.00085988 0.03132396"
        rpy="0 0 0" />
      <mass
        value="0.334134001274987" />
      <inertia
        ixx = "0.00057643"  ixy = "0.00000275"  ixz = "-0.00000921"
        iyx = "0.00000275"  iyy = "0.00361791"  iyz = "-0.00000422"
        izx = "-0.00000921" izy = "-0.00000422" izz = "0.00383778" />
    </inertial>
    
    <visual>
      <origin
        xyz="0 0 0"
        rpy="0 0 0" />
      <geometry>
        <mesh
          filename="package://standford_pupper_description/meshes/base_link.STL" />
      </geometry>
      <material
        name="">
        <color
          rgba="0.79216 0.81961 0.93333 1" />
      </material>
    </visual>
    <collision>
      <origin
        xyz="0 0 0"
        rpy="0 0 0" />
      <geometry>
        <mesh
          filename="package://standford_pupper_description/meshes/base_link.STL" />
      </geometry>
    </collision>
  </link>

 
    <link
    name="LF_HIP">
    <inertial>
      <origin
        xyz="0.03672908 0.02740814 0.00118127"
        rpy="0 0 0" />
      <mass
        value="0.09551479" />
    
      <inertia  ixx="8.36683671180298e-05" ixy="0" ixz="0" iyy="5.289856175366819e-05" iyz="0" izz="0.00010700079967936377" />
    </inertial>


  


    <visual>
      <origin
        xyz="0 0 0"
        rpy="0 0 0" />
      <geometry>
        <mesh
          filename="package://standford_pupper_description/meshes/LF_HIP.STL" />
      </geometry>
      <material
        name="">
        <color
          rgba="0.972549019607843 0.968627450980392 0.929411764705882 1" />
      </material>
    </visual>
    
  </link>
  <joint
    name="LF_HIP_JOINT"
    type="revolute">
    <origin
      xyz="0.0705 0.04 0.02425"
      rpy="0 0 0" />
    <parent
      link="base_link" />
    <child
      link="LF_HIP" />
    <dynamics damping="0.01" friction="0.0"/>
    <axis
      xyz="1 0 0" />
    <limit
      lower="-3.14"
      upper="3.14"
      effort="500"
      velocity="2.5" />
  </joint>
  <link
    name="LF_THIGH">
    <inertial>
      <origin
        xyz="-0.04486232 -0.00163039 -0.02816178"
        rpy="0 0 0" />
      <mass
        value="0.00699575" />
      <!-- <inertia
      ixx = "0.00000417"	ixy = "-0.00000035"	ixz = "0.00000641"
	    iyx = "-0.00000035"	iyy = "0.00001438"	iyz = "-0.00000025"
	    izx = "0.00000641"	izy = "-0.00000022"	izz = "0.00001033" /> -->
      <inertia  ixx="4.011071699334492e-06" ixy="0" ixz="0" iyy="1.1878402750199946e-05" iyz="0" izz="8.333714363349829e-06" />
      
    </inertial>


   
    <visual>
      <origin
        xyz="0 0 0"
        rpy="0 0 0" />
      <geometry>
        <mesh
          filename="package://standford_pupper_description/meshes/LF_THIGH.STL" />
      </geometry>
      <material
        name="">
        <color
          rgba="0.0980392156862745 0.0980392156862745 0.0980392156862745 1" />
      </material>
    </visual>
   
  </link>
  <joint
    name="LF_THIGH_JOINT"
    type="revolute">
     <origin
      xyz="0.02735 0.029523 0.0012724"
      rpy="0.11522 0.436332 0.1069" />
    <parent
      link="LF_HIP" />
    <child
      link="LF_THIGH" />
    <dynamics damping="0.01" friction="0.0"/>
    <axis
      xyz="0 1 0" />
    <limit
      lower="-3.14"
      upper="3.14"
      effort="500"
      velocity="2.5" />
  </joint>
  <link
    name="LF_THIGH_FOOT">
    <inertial>
      <origin
        xyz="0.04002073 0.00580157 -0.02456342"
        rpy="0 0 0" />
      <mass
        value="0.00294875" />

    <inertia  ixx="1.7657563311842582e-06" ixy="0" ixz="0" iyy="6.375349389948617e-06" iyz="0" izz="4.649776510347592e-06" />
    </inertial>
    <visual>
      <origin
        xyz="0 0 0"
        rpy="0 0 0" />
      <geometry>
        <mesh
          filename="package://standford_pupper_description/meshes/LF_THIGH_FOOT.STL" />
      </geometry>
      <material
        name="">
        <color
          rgba="0.0980392156862745 0.0980392156862745 0.0980392156862745 1" />
      </material>
    </visual>
   
  </link>
  <joint
    name="LF_THIGH_FOOT_JOINT"
    type="revolute">
    <origin
      xyz="0.022028 0.0023333 -0.12152"
      rpy="-3.1416 -2.35619 3.1416" />
      
    <parent
      link="LF_THIGH" />
    <child
      link="LF_THIGH_FOOT" />
    <dynamics damping="0.01" friction="0.0"/>
    <axis
      xyz="0 1 0" />
    <limit
      lower="-3.14"
      upper="3.14"
      effort="500"
      velocity="2.5" />
  </joint>

 
 
  <link
    name="RF_HIP">
    <inertial>
      <origin
        xyz="0.03672910 -0.02740818 0.00118127"
        rpy="0 0 0" />
      <mass
        value="0.09551481" />  
      <inertia  ixx="8.36683846374877e-05" ixy="0" ixz="0" iyy="5.289857283018561e-05" iyz="0" izz="0.00010700082208443836" />

    </inertial>
    <visual>
      <origin
        xyz="0 0 0"
        rpy="0 0 0" />
      <geometry>
        <mesh
          filename="package://standford_pupper_description/meshes/RF_HIP.STL" />
      </geometry>
      <material
        name="">
        <color
          rgba="0.972549019607843 0.968627450980392 0.929411764705882 1" />
      </material>
    </visual>
  
  </link>
  <joint
    name="RF_HIP_JOINT"
    type="revolute">
    <origin
      xyz="0.0705 -0.04 0.02425"
      rpy="0 0 0" />
    <parent
      link="base_link" />
    <child
      link="RF_HIP" />
    <dynamics damping="0.01" friction="0.0"/>
    <axis
      xyz="1 0 0" />
    <limit
      lower="-3.14"
      upper="3.14"
      effort="500"
      velocity="2.5" />
  </joint>
  <link
    name="RF_THIGH">
    <inertial>
      <origin
        xyz="-0.04407832 -0.00075984 -0.02770708"
        rpy="0 0 0" />
      <mass
        value="0.00716529" />
      <inertia  ixx="4.19386946486895e-06" ixy="0" ixz="0" iyy="1.2104016236055651e-05" iyz="0" izz="8.683526344065076e-06" />
    </inertial>
    <visual>
      <origin
        xyz="0 0 0"
        rpy="0 0 0" />
      <geometry>
        <mesh
          filename="package://standford_pupper_description/meshes/RF_THIGH.STL" />
      </geometry>
      <material
        name="">
        <color
          rgba="0.96078431372549 0.96078431372549 0.964705882352941 1" />
      </material>
    </visual>
  
  </link>
  <joint
    name="RF_THIGH_JOINT"
    type="revolute">
    <origin
      xyz="0.02735 -0.029523 0.0012724"
      rpy="-0.11522 0.436332 -0.1069" />
    <parent
      link="RF_HIP" />
    <child
      link="RF_THIGH" />
    <dynamics damping="0.01" friction="0.0"/>
    <axis
      xyz="0 1 0" />
    <limit
      lower="-3.14"
      upper="3.14"
      effort="500"
      velocity="2.5" />
  </joint>
  <link
    name="RF_THIGH_FOOT">
    <inertial>
      <origin
        xyz= "0.04002067 -0.00366667 -0.02497144"
        rpy="0 0 0" />
      <mass
        value="0.00294875" />
    <inertia  ixx="1.7524924876914674e-06" ixy="0" ixz="0" iyy="6.381194355258551e-06" iyz="0" izz="4.6306677015448675e-06" />
    </inertial>
    <visual>
      <origin
        xyz="0 0 0"
        rpy="0 0 0" />
      <geometry>
        <mesh
          filename="package://standford_pupper_description/meshes/RF_THIGH_FOOT.STL" />
      </geometry>
      <material
        name="">
        <color
          rgba="0.0980392156862745 0.0980392156862745 0.0980392156862745 1" />
      </material>
    </visual>
   
  </link>
  <joint
    name="RF_THIGH_FOOT_JOINT"
    type="revolute">
   <origin
      xyz="0.022028 -0.0023333 -0.12152"
      rpy="3.1416 -2.35619 -3.1416" />
    <parent
      link="RF_THIGH" />
    <child
      link="RF_THIGH_FOOT" />
    <dynamics damping="0.01" friction="0.0"/>
    <axis
      xyz="0 1 0" />
    <limit
      lower="-3.14"
      upper="3.14"
      effort="500"
      velocity="2.5" />
  </joint>

  <link
    name="LH_HIP">
    <inertial>
      <origin
        xyz="0.03712908 0.02740814 0.00118127"
        rpy="0 0 0" />
      <mass
        value="0.09551479" />
      <inertia  ixx="8.36683671180298e-05" ixy="0" ixz="0" iyy="5.289856175366819e-05" iyz="0" izz="0.00010700079967936377" />

    </inertial>

    <visual>
      <origin
        xyz="0 0 0"
        rpy="0 0 0" />
      <geometry>
        <mesh
          filename="package://standford_pupper_description/meshes/LH_HIP.STL" />
      </geometry>
      <material
        name="">
        <color
          rgba="0.972549019607843 0.968627450980392 0.929411764705882 1" />
      </material>
    </visual>
  
  </link>
  <joint
    name="LH_HIP_JOINT"
    type="revolute">
    <origin
      xyz="-0.1299 0.04 0.02425"
      rpy="0 0 0" />
    <parent
      link="base_link" />
    <child
      link="LH_HIP" />
    <dynamics damping="0.01" friction="0.0"/>
    <axis
      xyz="1 0 0" />
    <limit
      lower="-3.14"
      upper="3.14"
      effort="500"
      velocity="2.5" />
  </joint>
  <link
    name="LH_THIGH">
    <inertial>
      <origin
        xyz="-0.04407853 -0.00162684 -0.02766984"
        rpy="0 0 0" />
      <mass
        value="0.00716530" />
      <inertia  ixx="4.108284608117991e-06" ixy="0" ixz="0" iyy="1.2166289422293203e-05" iyz="0" izz="8.53569145948762e-06" />

    </inertial>

    <visual>
      <origin
        xyz="0 0 0"
        rpy="0 0 0" />
      <geometry>
        <mesh
          filename="package://standford_pupper_description/meshes/LH_THIGH.STL" />
      </geometry>
      <material
        name="">
        <color
          rgba="0.96078431372549 0.96078431372549 0.964705882352941 1" />
      </material>
    </visual>
  
  </link>
  <joint
    name="LH_THIGH_JOINT"
    type="revolute">
    <origin
      xyz="0.02775 0.029523 0.0012724"
      rpy="0.11522 0.436332 0.1069" />
    <parent
      link="LH_HIP" />
    <child
      link="LH_THIGH" />
    <dynamics damping="0.01" friction="0.0"/>
    <axis
      xyz="0 1 0" />
    <limit
      lower="-3.14"
      upper="3.14"
      effort="500"
      velocity="2.5" />
  </joint>
  <link
    name="LH_THIGH_FOOT">
    <inertial>
      <origin
        xyz="0.04002073 0.00551265 -0.02458837"
        rpy="0 0 0" />
      <mass
        value="0.00294875" />

    <inertia  ixx="1.7657563353229885e-06" ixy="0" ixz="0" iyy="6.375349389948617e-06" iyz="0" izz="4.649776514486322e-06" />

    </inertial>
    <visual>
      <origin
        xyz="0 0 0"
        rpy="0 0 0" />
      <geometry>
        <mesh
          filename="package://standford_pupper_description/meshes/LH_THIGH_FOOT.STL" />
      </geometry>
      <material
        name="">
        <color
          rgba="0.0980392156862745 0.0980392156862745 0.0980392156862745 1" />
      </material>
    </visual>
  
  </link>
  <joint
    name="LH_THIGH_FOOT_JOINT"
    type="revolute">
    <origin
      xyz="0.022028 0.0026233 -0.12152"
      rpy="-3.1416 -2.35619 3.1416" />
    <parent
      link="LH_THIGH" />
    <child
      link="LH_THIGH_FOOT" />
    <dynamics damping="0.01" friction="0.0"/>
    <axis
      xyz="0 1 0" />
    <limit
      lower="-3.14"
      upper="3.14"
      effort="500"
      velocity="2.5" />
  </joint>
  <link
    name="RH_HIP">
    <inertial>
      <origin
        xyz="-0.163418681352713 -0.0426100217140138 0.00185777526130817"
        rpy="0 0 0" />
      <mass
        value="0.09551481" />
      <inertia  ixx="8.36683846374877e-05" ixy="0" ixz="0" iyy="5.289856462259541e-05" iyz="0" izz="0.00010700081387684817" />

    </inertial>
    <visual>
      <origin
        xyz="0 0 0"
        rpy="0 0 0" />
      <geometry>
        <mesh
          filename="package://standford_pupper_description/meshes/RH_HIP.STL" />
      </geometry>
      <material
        name="">
        <color
          rgba="0.792156862745098 0.819607843137255 0.933333333333333 1" />
      </material>
    </visual>
   
  </link>
  <joint
    name="RH_HIP_JOINT"
    type="revolute">
    <origin
      xyz="0.0705 -0.04 0.02425"
      rpy="0 0 0" />
    <parent
      link="base_link" />
    <child
      link="RH_HIP" />
    <dynamics damping="0.01" friction="0.0"/>
    <axis
      xyz="1 0 0" />
    <limit
      lower="-3.14"
      upper="3.14"
      effort="500"
      velocity="2.5" />
  </joint>
  <link
    name="RH_THIGH">
    <inertial>
      <origin
        xyz="-0.04407832 0.00162685 -0.02766971"
        rpy="0 0 0" />
      <mass
        value="0.00716529" />
      <inertia  ixx="4.108278874534459e-06" ixy="0" ixz="0" iyy="1.2166272442837462e-05" iyz="0" izz="8.535679546948776e-06" />

    </inertial>
    <visual>
      <origin
        xyz="0 0 0"
        rpy="0 0 0" />
      <geometry>
        <mesh
          filename="package://standford_pupper_description/meshes/RH_THIGH.STL" />
      </geometry>
      <material
        name="">
        <color
          rgba="0.0980392156862745 0.0980392156862745 0.0980392156862745 1" />
      </material>
    </visual>
   
  </link>
  <joint
    name="RH_THIGH_JOINT"
    type="revolute">
    <origin
      xyz="-0.17265 -0.029523 0.0012724"
      rpy="-0.11522 0.436332 -0.1069" />
    <parent
      link="RH_HIP" />
    <child
      link="RH_THIGH" />
    <dynamics damping="0.01" friction="0.0"/>
    <axis
      xyz="0 1 0" />
    <limit
      lower="-3.14"
      upper="3.14"
      effort="500"
      velocity="2.5" />
  </joint>
  <link
    name="RH_THIGH_FOOT">
    <inertial>
      <origin
        xyz="0.04002067 -0.00341667 -0.02497144"
        rpy="0 0 0" />
      <mass
        value="0.00294875" />
    <inertia  ixx="1.7524924876914674e-06" ixy="0" ixz="0" iyy="6.381194355258551e-06" iyz="0" izz="4.6306677015448675e-06" />
    </inertial>
    <visual>
      <origin
        xyz="0 0 0"
        rpy="0 0 0" />
      <geometry>
        <mesh
          filename="package://standford_pupper_description/meshes/RH_THIGH_FOOT.STL" />
      </geometry>
      <collision>
      <origin
        xyz="0 0 0"
        rpy="0 0 0" />
      <geometry>
        <mesh
          filename="package://standford_pupper_description/meshes/RH_THIGH_FOOT.STL" />
      </geometry>
    </collision>
      <material
        name="">
        <color
          rgba="0.0980392156862745 0.0980392156862745 0.0980392156862745 1" />
      </material>
    </visual>
   
  </link>
  <joint
    name="RH_THIGH_FOOT_JOINT"
    type="revolute">
    <origin
      xyz="0.022028 -0.0025833 -0.12152"
      rpy="3.1416 -2.35619 -3.1416" />
    <parent
      link="RH_THIGH" />
    <child
      link="RH_THIGH_FOOT" />
    <dynamics damping="0.01" friction="0.0"/>
    <axis
      xyz="0 1 0" />
    <limit
      lower="-3.14"
      upper="3.14"
      effort="500"
      velocity="2.5" />
  </joint>

    <link name="RF_TOE">
    <inertial>
      <origin rpy="0 0 0" xyz="0 0 0"/>
    
      <mass value="0.002"/>
      <inertia ixx="2e-08" ixy="0" ixz="0" iyy="2e-08" iyz="0" izz="2e-08"/>
    </inertial>
  
    <visual>
    
      <origin rpy="0 0 0" xyz="0 0 0"/>
      <geometry>
        <sphere radius="0.005"/>
      </geometry>
    </visual>
    <collision>
      <origin rpy="0 0 0" xyz="0 0 0"/>
      <geometry>
        <sphere radius="0.005"/>
      </geometry>
    </collision>
  </link>
  <joint name="RF_TOE_JOINT" type="fixed">
    <origin rpy="0 0 0" xyz="-0.01 0 -0.116"/>
    <parent link="RF_THIGH_FOOT"/>
    <child link="RF_TOE"/>
  </joint>

   <link name="RH_TOE">
    <inertial>
      <origin rpy="0 0 0" xyz="0 0 0"/>
  
      <mass value="0.002"/>
      <inertia ixx="2e-08" ixy="0" ixz="0" iyy="2e-08" iyz="0" izz="2e-08"/>
    </inertial>
   
    <visual>
   
      <origin rpy="0 0 0" xyz="0 0 0"/>
      <geometry>
        <sphere radius="0.005"/>
      </geometry>
    </visual>
    <collision>
      <origin rpy="0 0 0" xyz="0 0 0"/>
      <geometry>
        <sphere radius="0.005"/>
      </geometry>
    </collision>
  </link>
  <joint name="RH_TOE_JOINT" type="fixed">
    <origin rpy="0 0 0" xyz="-0.01 0 -0.116"/>
    <parent link="RH_THIGH_FOOT"/>
    <child link="RH_TOE"/>
  </joint>

   <link name="LF_TOE">
    <inertial>
      <origin rpy="0 0 0" xyz="0 0 0"/>
  
      <mass value="0.002"/>
      <inertia ixx="2e-08" ixy="0" ixz="0" iyy="2e-08" iyz="0" izz="2e-08"/>
    </inertial>
 
    <visual>
 
      <origin rpy="0 0 0" xyz="0 0 0"/>
      <geometry>
        <sphere radius="0.005"/>
      </geometry>
    </visual>
    <collision>
      <origin rpy="0 0 0" xyz="0 0 0"/>
      <geometry>
        <sphere radius="0.005"/>
      </geometry>
    </collision>
  </link>

  <link name="LH_TOE">
    <inertial>
      <origin rpy="0 0 0" xyz="0 0 0"/>
    
      <mass value="0.002"/>
      <inertia ixx="2e-08" ixy="0" ixz="0" iyy="2e-08" iyz="0" izz="2e-08"/>
    </inertial>
  
    <visual>
    
      <origin rpy="0 0 0" xyz="0 0 0"/>
      <geometry>
        <sphere radius="0.005"/>
      </geometry>
    </visual>
    <collision>
      <origin rpy="0 0 0" xyz="0 0 0"/>
      <geometry>
        <sphere radius="0.005"/>
      </geometry>
    </collision>
  </link>
  <joint name="LH_TOE_JOINT" type="fixed">
    <origin rpy="0 0 0" xyz="-0.01 0 -0.116"/>
    <parent link="LH_THIGH_FOOT"/>
    <child link="LH_TOE"/>
  </joint>


  <joint name="LF_TOE_JOINT" type="fixed">
    <origin rpy="0 0 0" xyz="-0.01 0 -0.116"/>
    <parent link="LF_THIGH_FOOT"/>
    <child link="LF_TOE"/>
  </joint>

  <gazebo reference="LF_TOE">
    <kp>1000000.0</kp>
    <kd>1.0</kd>
    <mu1>0.8</mu1>
    <mu2>0.8</mu2>
    <maxVel>0.0</maxVel>
    <minDepth>0.001</minDepth>
  </gazebo>
  <gazebo reference="RF_TOE">
    <kp>1000000.0</kp>
    <kd>1.0</kd>
    <mu1>0.8</mu1>
    <mu2>0.8</mu2>
    <maxVel>0.0</maxVel>
    <minDepth>0.001</minDepth>
  </gazebo>
  <gazebo reference="LH_TOE">
    <kp>1000000.0</kp>
    <kd>1.0</kd>
    <mu1>0.8</mu1>
    <mu2>0.8</mu2>
    <maxVel>0.0</maxVel>
    <minDepth>0.001</minDepth>
  </gazebo>
  <gazebo reference="RH_TOE">
    <kp>1000000.0</kp>
    <kd>1.0</kd>
    <mu1>0.8</mu1>
    <mu2>0.8</mu2>
    <maxVel>0.0</maxVel>
    <minDepth>0.001</minDepth>
  </gazebo>


   <transmission name="tran1">
    <type>transmission_interface/SimpleTransmission</type>
    <robotNamespace>standford_pupper</robotNamespace>
    <joint name="LF_HIP_JOINT">
      <hardwareInterface>hardware_interface/EffortJointInterface</hardwareInterface>
    </joint>
    <actuator name="motor1">
      <mechanicalReduction>1</mechanicalReduction>
    </actuator>
  </transmission>
  <transmission name="tran2">
    <type>transmission_interface/SimpleTransmission</type>
    <robotNamespace>standford_pupper</robotNamespace>
    <joint name="RF_HIP_JOINT">
      <hardwareInterface>hardware_interface/EffortJointInterface</hardwareInterface>
    </joint>
    <actuator name="motor2">
      <mechanicalReduction>1</mechanicalReduction>
    </actuator>
  </transmission>
  <transmission name="tran3">
    <type>transmission_interface/SimpleTransmission</type>
    <robotNamespace>standford_pupper</robotNamespace>
    <joint name="LH_HIP_JOINT">
      <hardwareInterface>hardware_interface/EffortJointInterface</hardwareInterface>
    </joint>
    <actuator name="motor3">
      <mechanicalReduction>1</mechanicalReduction>
    </actuator>
  </transmission>
  <transmission name="tran4">
    <type>transmission_interface/SimpleTransmission</type>
    <robotNamespace>standford_pupper</robotNamespace>
    <joint name="RH_HIP_JOINT">
      <hardwareInterface>hardware_interface/EffortJointInterface</hardwareInterface>
    </joint>
    <actuator name="motor4">
      <mechanicalReduction>1</mechanicalReduction>
    </actuator>
  </transmission>
  <transmission name="tran5">
    <type>transmission_interface/SimpleTransmission</type>
    <robotNamespace>standford_pupper</robotNamespace>
    <joint name="LF_THIGH_JOINT">
      <hardwareInterface>hardware_interface/EffortJointInterface</hardwareInterface>
    </joint>
    <actuator name="motor5">
      <mechanicalReduction>1</mechanicalReduction>
    </actuator>
  </transmission>
  <transmission name="tran6">
    <type>transmission_interface/SimpleTransmission</type>
    <robotNamespace>standford_pupper</robotNamespace>
    <joint name="RF_THIGH_JOINT">
      <hardwareInterface>hardware_interface/EffortJointInterface</hardwareInterface>
    </joint>
    <actuator name="motor6">
      <mechanicalReduction>1</mechanicalReduction>
    </actuator>
  </transmission>
  <transmission name="tran7">
    <type>transmission_interface/SimpleTransmission</type>
    <robotNamespace>standford_pupper</robotNamespace>
    <joint name="LH_THIGH_JOINT">
      <hardwareInterface>hardware_interface/EffortJointInterface</hardwareInterface>
    </joint>
    <actuator name="motor7">
      <mechanicalReduction>1</mechanicalReduction>
    </actuator>
  </transmission>
  <transmission name="tran8">
    <type>transmission_interface/SimpleTransmission</type>
    <robotNamespace>standford_pupper</robotNamespace>
    <joint name="RH_THIGH_JOINT">
      <hardwareInterface>hardware_interface/EffortJointInterface</hardwareInterface>
    </joint>
    <actuator name="motor8">
      <mechanicalReduction>1</mechanicalReduction>
    </actuator>
  </transmission>
  <transmission name="tran9">
    <type>transmission_interface/SimpleTransmission</type>
    <robotNamespace>standford_pupper</robotNamespace>
    <joint name="LF_THIGH_FOOT_JOINT">
      <hardwareInterface>hardware_interface/EffortJointInterface</hardwareInterface>
    </joint>
    <actuator name="motor9">
      <mechanicalReduction>1</mechanicalReduction>
    </actuator>
  </transmission>
  <transmission name="tran10">
    <type>transmission_interface/SimpleTransmission</type>
    <robotNamespace>standford_pupper</robotNamespace>
    <joint name="RF_THIGH_FOOT_JOINT">
      <hardwareInterface>hardware_interface/EffortJointInterface</hardwareInterface>
    </joint>
    <actuator name="motor10">
      <mechanicalReduction>1</mechanicalReduction>
    </actuator>
  </transmission>
  <transmission name="tran11">
    <type>transmission_interface/SimpleTransmission</type>
    <robotNamespace>standford_pupper</robotNamespace>
    <joint name="LH_THIGH_FOOT_JOINT">
      <hardwareInterface>hardware_interface/EffortJointInterface</hardwareInterface>
    </joint>
    <actuator name="motor11">
      <mechanicalReduction>1</mechanicalReduction>
    </actuator>
  </transmission>
  <transmission name="tran12">
    <type>transmission_interface/SimpleTransmission</type>
    <robotNamespace>standford_pupper</robotNamespace>
    <joint name="RH_THIGH_FOOT_JOINT">
      <hardwareInterface>hardware_interface/EffortJointInterface</hardwareInterface>
    </joint>
    <actuator name="motor12">
      <mechanicalReduction>1</mechanicalReduction>
    </actuator>
  </transmission>
   <gazebo>
    <plugin filename="libhector_gazebo_ros_imu.so" name="imu_controller">
      <updateRate>50.0</updateRate>
      <bodyName>imu_link</bodyName>
      <topicName>imu/data</topicName>
      <accelDrift>0.005 0.005 0.005</accelDrift>
      <accelGaussianNoise>0.005 0.005 0.005</accelGaussianNoise>
      <rateDrift>0.005 0.005 0.005 </rateDrift>
      <rateGaussianNoise>0.005 0.005 0.005 </rateGaussianNoise>
      <headingDrift>0.005</headingDrift>
      <headingGaussianNoise>0.005</headingGaussianNoise>
    </plugin>
  </gazebo>
  <link name="imu_link">
    <inertial>
      <mass value="0.001"/>
      <origin rpy="0 0 0" xyz="0 0 0"/>
      <inertia ixx="1e-09" ixy="0.0" ixz="0.0" iyy="1e-09" iyz="0.0" izz="1e-09"/>
    </inertial>
  </link>
  <joint name="imu_joint" type="fixed">
    <parent link="base_link"/>
    <child link="imu_link"/>
  </joint>
   <gazebo>
    <plugin filename="libgazebo_ros_p3d.so" name="p3d_base_controller">
      <alwaysOn>true</alwaysOn>
      <updateRate>10.0</updateRate>
      <bodyName>base_link</bodyName>
      <topicName>odom/ground_truth</topicName>
      <gaussianNoise>0.01</gaussianNoise>
      <frameName>world</frameName>
      <xyzOffsets>0 0 0</xyzOffsets>
      <rpyOffsets>0 0 0</rpyOffsets>
    </plugin>
  </gazebo>

   <joint name="hokuyo_joint" type="fixed">
    <origin rpy="0 0 0" xyz="-0.05 0.0 0.1"/>
    <parent link="base_link"/>
    <child link="hokuyo_frame"/>
  </joint>
  <link name="hokuyo_frame">
    <inertial>
      <mass value="0.270"/>
      <origin rpy="0 0 0" xyz="0 0 0"/>
      <inertia ixx="2.632e-4" ixy="0" ixz="0" iyy="2.632e-4" iyz="0" izz="1.62e-4"/>
    </inertial>
    <visual>
      <origin rpy="0 0 0" xyz="0 0 0"/>
      <geometry>
        <mesh filename="package://hector_sensors_description/meshes/hokuyo_utm30lx/hokuyo_utm_30lx.dae"/>
      </geometry>
    </visual>
    <collision>
      <origin rpy="0 0 0" xyz="0 0 -0.0115"/>
      <geometry>
        <box size="0.058 0.058 0.087"/>
        <!--<mesh filename="package://hector_sensors_description/meshes/hokuyo_utm30lx/hokuyo_utm_30lx.stl"/>-->
      </geometry>
    </collision>
  </link>
  <gazebo reference="hokuyo_frame">
    <sensor name="hokuyo" type="ray">
      <always_on>true</always_on>
      <update_rate>30</update_rate>
      <pose>0 0 0 0 0 0</pose>
      <visualize>false</visualize>
      <ray>
        <scan>
          <horizontal>
            <samples>1040</samples>
            <resolution>1</resolution>
            <min_angle>2.2689280275926285</min_angle>
            <max_angle>-2.2689280275926285</max_angle>
          </horizontal>
        </scan>
        <range>
          <min>0.2</min>
          <max>30.0</max>
          <resolution>0.01</resolution>
        </range>
        <noise>
          <type>gaussian</type>
          <mean>0.0</mean>
          <stddev>0.004</stddev>
        </noise>
      </ray>
      <plugin filename="libgazebo_ros_laser.so" name="gazebo_ros_hokuyo_controller">
        <topicName>scan</topicName>
        <frameName>hokuyo_frame</frameName>
      </plugin>
    </sensor>
  </gazebo>
  <joint name="camera_joint" type="fixed">
    <origin rpy="0 0 0" xyz="0.098 0.0 0.082"/>
    <parent link="base_link"/>
    <child link="camera_link"/>
  </joint>
  <link name="camera_link">
    <inertial>
      <mass value="0.200"/>
      <origin rpy="0 0 0" xyz="0 0 0"/>
      <inertia ixx="5.8083e-4" ixy="0" ixz="0" iyy="3.0833e-5" iyz="0" izz="5.9083e-4"/>
    </inertial>
    <visual>
      <origin rpy="0 0 0" xyz="0 0 0"/>
      <geometry>
        <mesh filename="package://hector_sensors_description/meshes/asus_camera/asus_camera_simple.dae"/>
      </geometry>
    </visual>
    <!--        
       <collision>
          <origin xyz="0 0 0" rpy="0 0 0" />
          <geometry>
            <box size="0.035 0.185 0.025"/>
          </geometry>
        </collision>
        -->
    <collision>
      <origin rpy="0 0 0" xyz="0 0 0"/>
      <geometry>
        <mesh filename="package://hector_sensors_description/meshes/asus_camera/asus_camera_simple.dae"/>
      </geometry>
    </collision>
  </link>
  <joint name="camera_depth_joint" type="fixed">
    <origin rpy="0 0 0" xyz="0.0 0.049 0.0"/>
    <parent link="camera_link"/>
    <child link="camera_depth_frame"/>
  </joint>
  <link name="camera_depth_frame"/>
  <joint name="camera_depth_optical_joint" type="fixed">
    <origin rpy="-1.5707963267948966 0.0 -1.5707963267948966" xyz="0 0 0"/>
    <parent link="camera_depth_frame"/>
    <child link="camera_depth_optical_frame"/>
  </joint>
  <link name="camera_depth_optical_frame"/>
  <joint name="camera_rgb_joint" type="fixed">
    <origin rpy="0 0 0" xyz="0.0 0.022 0.0"/>
    <parent link="camera_link"/>
    <child link="camera_rgb_frame"/>
  </joint>
  <link name="camera_rgb_frame"/>
  <joint name="camera_rgb_optical_joint" type="fixed">
    <origin rpy="-1.5707963267948966 0.0 -1.5707963267948966" xyz="0 0 0"/>
    <parent link="camera_rgb_frame"/>
    <child link="camera_rgb_optical_frame"/>
  </joint>
  <link name="camera_rgb_optical_frame"/>
  <!-- ASUS Xtion PRO camera for simulation -->
  <gazebo reference="camera_depth_frame">
    <sensor name="camera" type="depth">
      <update_rate>20</update_rate>
      <camera>
        <horizontal_fov>1.0960667702524387</horizontal_fov>
        <image>
          <format>R8G8B8</format>
          <width>640</width>
          <height>480</height>
        </image>
        <clip>
          <near>0.5</near>
          <far>9</far>
        </clip>
      </camera>
      <plugin filename="libgazebo_ros_openni_kinect.so" name="camera_camera_controller">
        <imageTopicName>camera/rgb/image_raw</imageTopicName>
        <cameraInfoTopicName>camera/rgb/camera_info</cameraInfoTopicName>
        <depthImageTopicName>camera/depth/image_raw</depthImageTopicName>
        <depthImageCameraInfoTopicName>camera/depth/camera_info</depthImageCameraInfoTopicName>
        <pointCloudTopicName>camera/depth/points</pointCloudTopicName>
        <frameName>camera_depth_optical_frame</frameName>
      </plugin>
    </sensor>
  </gazebo>

   
</robot>