<?xml version="1.0" encoding="utf-8"?>
<!-- =================================================================================== -->
<!-- |    This document was autogenerated by xacro from stochlite.urdf.xacro           | -->
<!-- |    EDITING THIS FILE BY HAND IS NOT RECOMMENDED                                 | -->
<!-- =================================================================================== -->
<robot name="stochlite">
  <link name="world">
            </link>
  <joint name="fixed" type="fixed">
    <parent link="world"/>
    <child link="base_link"/>
  </joint>
  <link name="base_link">
    <inertial>
      <origin rpy="0 0 0" xyz="0.00011698 0.00043344 -0.0081282"/>
      <mass value="1.582"/>
      <inertia ixx="0.00575867" ixy="7.19E-06" ixz="3.71E-06" iyy="0.02534052" iyz="1.38E-06" izz="0.03025755"/>
    </inertial>
    <visual>
      <origin rpy="0 0 0" xyz="0 0 0"/>
      <geometry>
        <mesh filename="package://stochlite_description/meshes/base_link.STL"/>
      </geometry>
      <material name="">
        <color rgba="0.75294 0.75294 0.75294 1"/>
      </material>
    </visual>
    <collision>
      <origin rpy="0 0 0" xyz="0 0 0"/>
      <geometry>
        <mesh filename="package://stochlite_description/meshes/base_link.STL"/>
      </geometry>
    </collision>
  </link>
  <link name="fl_abd_link">
    <inertial>
      <origin rpy="0 0 0" xyz="0.0029662 0.011479 4.5103E-17"/>
      <mass value="0.037"/>
      <inertia ixx="0.00043261" ixy="0.00067195" ixz="-3.148E-05" iyy="0.00109285" iyz="-1.979E-05" izz="0.00151879"/>
    </inertial>
    <visual>
      <origin rpy="0 0 0" xyz="0 0 0"/>
      <geometry>
        <mesh filename="package://stochlite_description/meshes/fl_abd_link.STL"/>
      </geometry>
      <material name="">
        <color rgba="0.75294 0.75294 0.75294 1"/>
      </material>
    </visual>
    <collision>
      <origin rpy="0 0 0" xyz="0 0 0"/>
      <geometry>
        <mesh filename="package://stochlite_description/meshes/fl_abd_link.STL"/>
      </geometry>
    </collision>
  </link>
  <joint name="fl_abd_joint" type="revolute">
    <origin rpy="0 0 0" xyz="0.16695 0.0956 -0.0050001"/>
    <parent link="base_link"/>
    <child link="fl_abd_link"/>
    <axis xyz="1 0 0"/>
    <limit effort="4.1" lower="-10.22" upper="10.22" velocity="4.6"/>
  </joint>
  <link name="fl_thigh_link">
    <inertial>
      <origin rpy="0 0 0" xyz="-1.9979E-05 -0.0017695 -0.073"/>
      <mass value="0.32"/>
      <inertia ixx="0.00983483" ixy="0.00779081" ixz="-0.0041665" iyy="0.01193972" iyz="-0.00364492" izz="0.01581035"/>
    </inertial>
    <visual>
      <origin rpy="0 0 0" xyz="0 0 0"/>
      <geometry>
        <mesh filename="package://stochlite_description/meshes/fl_thigh_link.STL"/>
      </geometry>
      <material name="">
        <color rgba="0.75294 0.75294 0.75294 1"/>
      </material>
    </visual>
    <collision>
      <origin rpy="0 0 0" xyz="0 0 0"/>
      <geometry>
        <mesh filename="package://stochlite_description/meshes/fl_thigh_link.STL"/>
      </geometry>
    </collision>
  </link>
  <joint name="fl_hip_joint" type="revolute">
    <origin rpy="0 0 0" xyz="0 0.052019 0"/>
    <parent link="fl_abd_link"/>
    <child link="fl_thigh_link"/>
    <axis xyz="0 1 0"/>
    <limit effort="4.1" lower="-10.22" upper="10.22" velocity="4.6"/>
  </joint>
  <link name="fl_shank_link">
    <inertial>
      <origin rpy="0 0 0" xyz="4.6786E-08 0.014581 -0.08739"/>
      <mass value="0.055"/>
      <inertia ixx="0.00511956" ixy="0.00170322" ixz="-0.0021654" iyy="0.00476045" iyz="-0.00242252" izz="0.00343153"/>
    </inertial>
    <visual>
      <origin rpy="0 0 0" xyz="0 0 0"/>
      <geometry>
        <mesh filename="package://stochlite_description/meshes/fl_shank_link.STL"/>
      </geometry>
      <material name="">
        <color rgba="0.75294 0.75294 0.75294 1"/>
      </material>
    </visual>
    <collision>
      <origin rpy="0 0 0" xyz="0 0 0"/>
      <geometry>
        <mesh filename="package://stochlite_description/meshes/fl_shank_link.STL"/>
      </geometry>
    </collision>
  </link>
  <joint name="fl_knee_joint" type="revolute">
    <origin rpy="0 0 0" xyz="0 0.023481 -0.146"/>
    <parent link="fl_thigh_link"/>
    <child link="fl_shank_link"/>
    <axis xyz="0 1 0"/>
    <limit effort="4.1" lower="-10.22" upper="10.22" velocity="4.6"/>
  </joint>
  <link name="fl_toe_link">
        </link>
  <joint name="fl_toe_joint" type="fixed">
    <origin rpy="0 0 0" xyz="0 0.023481 -0.169"/>
    <axis xyz="0 1 0"/>
    <parent link="fl_shank_link"/>
    <child link="fl_toe_link"/>
  </joint>
  <link name="fr_abd_link">
    <inertial>
      <origin rpy="0 0 0" xyz="0.0029662 -0.011479 0"/>
      <mass value="0.037"/>
      <inertia ixx="0.00043896" ixy="-0.00067699" ixz="-3.147E-05" iyy="0.0010929" iyz="1.993E-05" izz="0.0015252"/>
    </inertial>
    <visual>
      <origin rpy="0 0 0" xyz="0 0 0"/>
      <geometry>
        <mesh filename="package://stochlite_description/meshes/fr_abd_link.STL"/>
      </geometry>
      <material name="">
        <color rgba="0.75294 0.75294 0.75294 1"/>
      </material>
    </visual>
    <collision>
      <origin rpy="0 0 0" xyz="0 0 0"/>
      <geometry>
        <mesh filename="package://stochlite_description/meshes/fr_abd_link.STL"/>
      </geometry>
    </collision>
  </link>
  <joint name="fr_abd_joint" type="revolute">
    <origin rpy="0 0 0" xyz="0.16695 -0.0964 -0.0049999"/>
    <parent link="base_link"/>
    <child link="fr_abd_link"/>
    <axis xyz="1 0 0"/>
    <limit effort="4.1" lower="-10.22" upper="10.22" velocity="4.6"/>
  </joint>
  <link name="fr_thigh_link">
    <inertial>
      <origin rpy="0 0 0" xyz="1.9979E-05 0.0017695 -0.073"/>
      <mass value="0.32"/>
      <inertia ixx="0.0099097" ixy="-0.00783571" ixz="-0.00416764" iyy="0.01194464" iyz="0.00366487" izz="0.01589016"/>
    </inertial>
    <visual>
      <origin rpy="0 0 0" xyz="0 0 0"/>
      <geometry>
        <mesh filename="package://stochlite_description/meshes/fr_thigh_link.STL"/>
      </geometry>
      <material name="">
        <color rgba="0.75294 0.75294 0.75294 1"/>
      </material>
    </visual>
    <collision>
      <origin rpy="0 0 0" xyz="0 0 0"/>
      <geometry>
        <mesh filename="package://stochlite_description/meshes/fr_thigh_link.STL"/>
      </geometry>
    </collision>
  </link>
  <joint name="fr_hip_joint" type="revolute">
    <origin rpy="0 0 0" xyz="0 -0.052019 0"/>
    <parent link="fr_abd_link"/>
    <child link="fr_thigh_link"/>
    <axis xyz="0 1 0"/>
    <limit effort="4.1" lower="-10.22" upper="10.22" velocity="4.6"/>
  </joint>
  <link name="fr_shank_link">
    <inertial>
      <origin rpy="0 0 0" xyz="-4.6856E-08 -0.014581 -0.08739"/>
      <mass value="0.055"/>
      <inertia ixx="0.00513592" ixy="-0.00171056" ixz="-0.0021654" iyy="0.00476044" iyz="0.0024329" izz="0.00344789"/>
    </inertial>
    <visual>
      <origin rpy="0 0 0" xyz="0 0 0"/>
      <geometry>
        <mesh filename="package://stochlite_description/meshes/fr_shank_link.STL"/>
      </geometry>
      <material name="">
        <color rgba="0.75294 0.75294 0.75294 1"/>
      </material>
    </visual>
    <collision>
      <origin rpy="0 0 0" xyz="0 0 0"/>
      <geometry>
        <mesh filename="package://stochlite_description/meshes/fr_shank_link.STL"/>
      </geometry>
    </collision>
  </link>
  <joint name="fr_knee_joint" type="revolute">
    <origin rpy="0 0 0" xyz="0 -0.023481 -0.146"/>
    <parent link="fr_thigh_link"/>
    <child link="fr_shank_link"/>
    <axis xyz="0 1 0"/>
    <limit effort="4.1" lower="-10.22" upper="10.22" velocity="4.6"/>
  </joint>
  <link name="fr_toe_link">
        </link>
  <joint name="fr_toe_joint" type="fixed">
    <origin rpy="0 0 0" xyz="0 -0.023481 -0.169"/>
    <axis xyz="0 1 0"/>
    <parent link="fr_shank_link"/>
    <child link="fr_toe_link"/>
  </joint>
  <link name="bl_abd_link">
    <inertial>
      <origin rpy="0 0 0" xyz="-0.0029662 0.011479 -4.6838E-17"/>
      <mass value="0.037"/>
      <inertia ixx="0.00043261" ixy="-0.00067195" ixz="3.147E-05" iyy="0.0010929" iyz="-1.979E-05" izz="0.0051879"/>
    </inertial>
    <visual>
      <origin rpy="0 0 0" xyz="0 0 0"/>
      <geometry>
        <mesh filename="package://stochlite_description/meshes/bl_abd_link.STL"/>
      </geometry>
      <material name="">
        <color rgba="0.75294 0.75294 0.75294 1"/>
      </material>
    </visual>
    <collision>
      <origin rpy="0 0 0" xyz="0 0 0"/>
      <geometry>
        <mesh filename="package://stochlite_description/meshes/bl_abd_link.STL"/>
      </geometry>
    </collision>
  </link>
  <joint name="bl_abd_joint" type="revolute">
    <origin rpy="0 0 0" xyz="-0.16695 0.0956 -0.0049999"/>
    <parent link="base_link"/>
    <child link="bl_abd_link"/>
    <axis xyz="1 0 0"/>
    <limit effort="4.1" lower="-10.22" upper="10.22" velocity="4.6"/>
  </joint>
  <link name="bl_thigh_link">
    <inertial>
      <origin rpy="0 0 0" xyz="-1.998E-05 -0.0017695 -0.073"/>
      <mass value="0.32"/>
      <inertia ixx="0.0098348" ixy="-0.007793" ixz="0.0041676" iyy="0.011945" iyz="-0.0036449" izz="0.015815"/>
    </inertial>
    <visual>
      <origin rpy="0 0 0" xyz="0 0 0"/>
      <geometry>
        <mesh filename="package://stochlite_description/meshes/bl_thigh_link.STL"/>
      </geometry>
      <material name="">
        <color rgba="0.75294 0.75294 0.75294 1"/>
      </material>
    </visual>
    <collision>
      <origin rpy="0 0 0" xyz="0 0 0"/>
      <geometry>
        <mesh filename="package://stochlite_description/meshes/bl_thigh_link.STL"/>
      </geometry>
    </collision>
  </link>
  <joint name="bl_hip_joint" type="revolute">
    <origin rpy="0 0 0" xyz="0 0.052019 0"/>
    <parent link="bl_abd_link"/>
    <child link="bl_thigh_link"/>
    <axis xyz="0 1 0"/>
    <limit effort="4.1" lower="-10.22" upper="10.22" velocity="4.6"/>
  </joint>
  <link name="bl_shank_link">
    <inertial>
      <origin rpy="0 0 0" xyz="4.678E-08 0.014581 -0.08739"/>
      <mass value="0.055"/>
      <inertia ixx="0.0051196" ixy="-0.0017032" ixz="0.0021654" iyy="0.0047604" iyz="-0.0024225" izz="0.0034315"/>
    </inertial>
    <visual>
      <origin rpy="0 0 0" xyz="0 0 0"/>
      <geometry>
        <mesh filename="package://stochlite_description/meshes/bl_shank_link.STL"/>
      </geometry>
      <material name="">
        <color rgba="0.75294 0.75294 0.75294 1"/>
      </material>
    </visual>
    <collision>
      <origin rpy="0 0 0" xyz="0 0 0"/>
      <geometry>
        <mesh filename="package://stochlite_description/meshes/bl_shank_link.STL"/>
      </geometry>
    </collision>
  </link>
  <joint name="bl_knee_joint" type="revolute">
    <origin rpy="0 0 0" xyz="0 0.023481 -0.146"/>
    <parent link="bl_thigh_link"/>
    <child link="bl_shank_link"/>
    <axis xyz="0 1 0"/>
    <limit effort="4.1" lower="-10.22" upper="10.22" velocity="4.6"/>
  </joint>
  <link name="bl_toe_link">
        </link>
  <joint name="bl_toe_joint" type="fixed">
    <origin rpy="0 0 0" xyz="0 0.023481 -0.169"/>
    <axis xyz="0 1 0"/>
    <parent link="bl_shank_link"/>
    <child link="bl_toe_link"/>
  </joint>
  <link name="br_abd_link">
    <inertial>
      <origin rpy="0 0 0" xyz="-0.0029662 -0.011479 6.4185E-17"/>
      <mass value="0.037"/>
      <inertia ixx="0.00043896" ixy="0.00067699" ixz="3.148E-05" iyy="0.0010929" iyz="1.994E-05" izz="0.0015252"/>
    </inertial>
    <visual>
      <origin rpy="0 0 0" xyz="0 0 0"/>
      <geometry>
        <mesh filename="package://stochlite_description/meshes/br_abd_link.STL"/>
      </geometry>
      <material name="">
        <color rgba="0.75294 0.75294 0.75294 1"/>
      </material>
    </visual>
    <collision>
      <origin rpy="0 0 0" xyz="0 0 0"/>
      <geometry>
        <mesh filename="package://stochlite_description/meshes/br_abd_link.STL"/>
      </geometry>
    </collision>
  </link>
  <joint name="br_abd_joint" type="revolute">
    <origin rpy="0 0 0" xyz="-0.16695 -0.0964 -0.0050001"/>
    <parent link="base_link"/>
    <child link="br_abd_link"/>
    <axis xyz="1 0 0"/>
    <limit effort="4.1" lower="-10.22" upper="10.22" velocity="4.6"/>
  </joint>
  <link name="br_thigh_link">
    <inertial>
      <origin rpy="0 0 0" xyz="1.998E-05 0.0017695 -0.073"/>
      <mass value="0.32"/>
      <inertia ixx="0.0099097" ixy="0.0078336" ixz="0.0041665" iyy="0.01194" iyz="0.0036649" izz="0.015885"/>
    </inertial>
    <visual>
      <origin rpy="0 0 0" xyz="0 0 0"/>
      <geometry>
        <mesh filename="package://stochlite_description/meshes/br_thigh_link.STL"/>
      </geometry>
      <material name="">
        <color rgba="0.75294 0.75294 0.75294 1"/>
      </material>
    </visual>
    <collision>
      <origin rpy="0 0 0" xyz="0 0 0"/>
      <geometry>
        <mesh filename="package://stochlite_description/meshes/br_thigh_link.STL"/>
      </geometry>
    </collision>
  </link>
  <joint name="br_hip_joint" type="revolute">
    <origin rpy="0 0 0" xyz="0 -0.052019 0"/>
    <parent link="br_abd_link"/>
    <child link="br_thigh_link"/>
    <axis xyz="0 1 0"/>
    <limit effort="4.1" lower="-10.22" upper="10.22" velocity="4.6"/>
  </joint>
  <link name="br_shank_link">
    <inertial>
      <origin rpy="0 0 0" xyz="-4.6786E-08 -0.014581 -0.08739"/>
      <mass value="0.055"/>
      <inertia ixx="0.00513592" ixy="0.00171056" ixz="0.0021654" iyy="0.00476045" iyz="0.0024329" izz="0.00344789"/>
    </inertial>
    <visual>
      <origin rpy="0 0 0" xyz="0 0 0"/>
      <geometry>
        <mesh filename="package://stochlite_description/meshes/br_shank_link.STL"/>
      </geometry>
      <material name="">
        <color rgba="0.75294 0.75294 0.75294 1"/>
      </material>
    </visual>
    <collision>
      <origin rpy="0 0 0" xyz="0 0 0"/>
      <geometry>
        <mesh filename="package://stochlite_description/meshes/br_shank_link.STL"/>
      </geometry>
    </collision>
  </link>
  <joint name="br_knee_joint" type="revolute">
    <origin rpy="0 0 0" xyz="0 -0.023481 -0.146"/>
    <parent link="br_thigh_link"/>
    <child link="br_shank_link"/>
    <axis xyz="0 1 0"/>
    <limit effort="4.1" lower="-10.22" upper="10.22" velocity="4.6"/>
  </joint>
  <link name="br_toe_link">
        </link>
  <joint name="br_toe_joint" type="fixed">
    <origin rpy="0 0 0" xyz="0 -0.023481 -0.169"/>
    <axis xyz="0 1 0"/>
    <parent link="br_shank_link"/>
    <child link="br_toe_link"/>
  </joint>
  <link name="fl_leg_frame">
        </link>
  <link name="fr_leg_frame">
        </link>
  <link name="bl_leg_frame">
        </link>
  <link name="br_leg_frame">
        </link>
  <joint name="fl_fixed" type="fixed">
    <parent link="base_link"/>
    <child link="fl_leg_frame"/>
    <origin rpy="0 0 0" xyz="0.16695 0.0956 -0.0050001"/>
    <axis xyz="1 0 0"/>
  </joint>
  <joint name="fr_fixed" type="fixed">
    <parent link="base_link"/>
    <child link="fr_leg_frame"/>
    <origin rpy="0 0 0" xyz="0.16695 -0.0964 -0.0049999"/>
    <axis xyz="1 0 0"/>
  </joint>
  <joint name="bl_fixed" type="fixed">
    <parent link="base_link"/>
    <child link="bl_leg_frame"/>
    <origin rpy="0 0 0" xyz="-0.16695 0.0956 -0.0049999"/>
    <axis xyz="1 0 0"/>
  </joint>
  <joint name="br_fixed" type="fixed">
    <parent link="base_link"/>
    <child link="br_leg_frame"/>
    <origin rpy="0 0 0" xyz="-0.16695 -0.0964 -0.0050001"/>
    <axis xyz="1 0 0"/>
  </joint>
  <transmission name="fl_abd_trans">
    <type>transmission_interface/SimpleTransmission</type>
    <joint name="fl_abd_joint">
      <hardwareInterface>hardware_interface/EffortJointInterface</hardwareInterface>
    </joint>
    <actuator name="fl_abd_motor">
      <mechanicalReduction>1</mechanicalReduction>
    </actuator>
  </transmission>
  <transmission name="fl_hip_trans">
    <type>transmission_interface/SimpleTransmission</type>
    <joint name="fl_hip_joint">
      <hardwareInterface>hardware_interface/EffortJointInterface</hardwareInterface>
    </joint>
    <actuator name="fl_hip_motor">
      <mechanicalReduction>1</mechanicalReduction>
    </actuator>
  </transmission>
  <transmission name="fl_knee_trans">
    <type>transmission_interface/SimpleTransmission</type>
    <joint name="fl_knee_joint">
      <hardwareInterface>hardware_interface/EffortJointInterface</hardwareInterface>
    </joint>
    <actuator name="fl_knee_motor">
      <mechanicalReduction>1</mechanicalReduction>
    </actuator>
  </transmission>
  <transmission name="bl_abd_trans">
    <type>transmission_interface/SimpleTransmission</type>
    <joint name="bl_abd_joint">
      <hardwareInterface>hardware_interface/EffortJointInterface</hardwareInterface>
    </joint>
    <actuator name="bl_abd_motor">
      <mechanicalReduction>1</mechanicalReduction>
    </actuator>
  </transmission>
  <transmission name="bl_hip_trans">
    <type>transmission_interface/SimpleTransmission</type>
    <joint name="bl_hip_joint">
      <hardwareInterface>hardware_interface/EffortJointInterface</hardwareInterface>
    </joint>
    <actuator name="bl_hip_motor">
      <mechanicalReduction>1</mechanicalReduction>
    </actuator>
  </transmission>
  <transmission name="bl_knee_trans">
    <type>transmission_interface/SimpleTransmission</type>
    <joint name="bl_knee_joint">
      <hardwareInterface>hardware_interface/EffortJointInterface</hardwareInterface>
    </joint>
    <actuator name="bl_knee_motor">
      <mechanicalReduction>1</mechanicalReduction>
    </actuator>
  </transmission>
  <transmission name="fr_abd_trans">
    <type>transmission_interface/SimpleTransmission</type>
    <joint name="fr_abd_joint">
      <hardwareInterface>hardware_interface/EffortJointInterface</hardwareInterface>
    </joint>
    <actuator name="fr_abd_motor">
      <mechanicalReduction>1</mechanicalReduction>
    </actuator>
  </transmission>
  <transmission name="fr_hip_trans">
    <type>transmission_interface/SimpleTransmission</type>
    <joint name="fr_hip_joint">
      <hardwareInterface>hardware_interface/EffortJointInterface</hardwareInterface>
    </joint>
    <actuator name="fr_hip_motor">
      <mechanicalReduction>1</mechanicalReduction>
    </actuator>
  </transmission>
  <transmission name="fr_knee_trans">
    <type>transmission_interface/SimpleTransmission</type>
    <joint name="fr_knee_joint">
      <hardwareInterface>hardware_interface/EffortJointInterface</hardwareInterface>
    </joint>
    <actuator name="fr_knee_motor">
      <mechanicalReduction>1</mechanicalReduction>
    </actuator>
  </transmission>
  <transmission name="br_abd_trans">
    <type>transmission_interface/SimpleTransmission</type>
    <joint name="br_abd_joint">
      <hardwareInterface>hardware_interface/EffortJointInterface</hardwareInterface>
    </joint>
    <actuator name="br_abd_motor">
      <mechanicalReduction>1</mechanicalReduction>
    </actuator>
  </transmission>
  <transmission name="br_hip_trans">
    <type>transmission_interface/SimpleTransmission</type>
    <joint name="br_hip_joint">
      <hardwareInterface>hardware_interface/EffortJointInterface</hardwareInterface>
    </joint>
    <actuator name="br_hip_motor">
      <mechanicalReduction>1</mechanicalReduction>
    </actuator>
  </transmission>
  <transmission name="br_knee_trans">
    <type>transmission_interface/SimpleTransmission</type>
    <joint name="br_knee_joint">
      <hardwareInterface>hardware_interface/EffortJointInterface</hardwareInterface>
    </joint>
    <actuator name="br_knee_motor">
      <mechanicalReduction>1</mechanicalReduction>
    </actuator>
  </transmission>
  <gazebo reference="base_link_link">
    <material>Gazebo/White</material>
    <kp>10000000.0</kp>
    <kd>1.0</kd>
    <mu1>4.0</mu1>
    <mu2>4.0</mu2>
    <maxVel>0.0</maxVel>
    <minDepth>0.001</minDepth>
  </gazebo>
  <gazebo reference="fl_abd_link">
    <material>Gazebo/Grey</material>
    <kp>10000000.0</kp>
    <kd>1.0</kd>
    <mu1>4.0</mu1>
    <mu2>4.0</mu2>
    <maxVel>0.0</maxVel>
    <minDepth>0.001</minDepth>
  </gazebo>
  <gazebo reference="bl_abd_link">
    <material>Gazebo/Grey</material>
    <kp>10000000.0</kp>
    <kd>1.0</kd>
    <mu1>4.0</mu1>
    <mu2>4.0</mu2>
    <maxVel>0.0</maxVel>
    <minDepth>0.001</minDepth>
  </gazebo>
  <gazebo reference="fr_abd_link">
    <material>Gazebo/Grey</material>
    <kp>10000000.0</kp>
    <kd>1.0</kd>
    <mu1>4.0</mu1>
    <mu2>4.0</mu2>
    <maxVel>0.0</maxVel>
    <minDepth>0.001</minDepth>
  </gazebo>
  <gazebo reference="br_abd_link">
    <material>Gazebo/Grey</material>
    <kp>10000000.0</kp>
    <kd>1.0</kd>
    <mu1>4.0</mu1>
    <mu2>4.0</mu2>
    <maxVel>0.0</maxVel>
    <minDepth>0.001</minDepth>
  </gazebo>
  <gazebo reference="fl_thigh_link">
    <material>Gazebo/DarkGrey</material>
    <kp>10000000.0</kp>
    <kd>1.0</kd>
    <mu1>4.0</mu1>
    <mu2>4.0</mu2>
    <maxVel>0.0</maxVel>
    <minDepth>0.001</minDepth>
  </gazebo>
  <gazebo reference="bl_thigh_link">
    <material>Gazebo/DarkGrey</material>
    <kp>10000000.0</kp>
    <kd>1.0</kd>
    <mu1>4.0</mu1>
    <mu2>4.0</mu2>
    <maxVel>0.0</maxVel>
    <minDepth>0.001</minDepth>
  </gazebo>
  <gazebo reference="fr_thigh_link">
    <material>Gazebo/DarkGrey</material>
    <kp>10000000.0</kp>
    <kd>1.0</kd>
    <mu1>4.0</mu1>
    <mu2>4.0</mu2>
    <maxVel>0.0</maxVel>
    <minDepth>0.001</minDepth>
  </gazebo>
  <gazebo reference="br_thigh_link">
    <material>Gazebo/DarkGrey</material>
    <kp>10000000.0</kp>
    <kd>1.0</kd>
    <mu1>4.0</mu1>
    <mu2>4.0</mu2>
    <maxVel>0.0</maxVel>
    <minDepth>0.001</minDepth>
  </gazebo>
  <gazebo reference="fl_shank_link">
    <material>Gazebo/Grey</material>
    <kp>10000000.0</kp>
    <kd>1.0</kd>
    <mu1>4.0</mu1>
    <mu2>4.0</mu2>
    <maxVel>0.0</maxVel>
    <minDepth>0.001</minDepth>
  </gazebo>
  <gazebo reference="bl_shank_link">
    <material>Gazebo/Grey</material>
    <kp>10000000.0</kp>
    <kd>1.0</kd>
    <mu1>4.0</mu1>
    <mu2>4.0</mu2>
    <maxVel>0.0</maxVel>
    <minDepth>0.001</minDepth>
  </gazebo>
  <gazebo reference="fr_shank_link">
    <material>Gazebo/Grey</material>
    <kp>10000000.0</kp>
    <kd>1.0</kd>
    <mu1>4.0</mu1>
    <mu2>4.0</mu2>
    <maxVel>0.0</maxVel>
    <minDepth>0.001</minDepth>
  </gazebo>
  <gazebo reference="br_shank_link">
    <material>Gazebo/Grey</material>
    <kp>10000000.0</kp>
    <kd>1.0</kd>
    <mu1>4.0</mu1>
    <mu2>4.0</mu2>
    <maxVel>0.0</maxVel>
    <minDepth>0.001</minDepth>
  </gazebo>
  <!-- Enable the Joint Control -->
  <gazebo>
    <plugin filename="libgazebo_ros_control.so" name="gazebo_ros_control">
      <legacyModeNS>true</legacyModeNS>
    </plugin>
  </gazebo>
  <gazebo>
    <self_collide>1</self_collide>
  </gazebo>
  <gazebo>
    <plugin filename="libgazebo_ros_p3d.so" name="p3d_base_controller">
      <alwaysOn>true</alwaysOn>
      <updateRate>10.0</updateRate>
      <bodyName>base_link</bodyName>
      <topicName>odom/ground_truth</topicName>
      <gaussianNoise>0.01</gaussianNoise>
      <frameName>world</frameName>
      <xyzOffsets>0 0 0</xyzOffsets>
      <rpyOffsets>0 0 0</rpyOffsets>
    </plugin>
  </gazebo>
  <link name="imu_link_1">
    <inertial>
      <mass value="0.001"/>
      <origin rpy="0 0 0" xyz="0 0 0"/>
      <inertia ixx="1e-09" ixy="0.0" ixz="0.0" iyy="1e-09" iyz="0.0" izz="1e-09"/>
    </inertial>
    <visual>
      <origin rpy="0 0 0" xyz="0 0 0"/>
      <geometry>
        <box size="0.005 0.005 0.005"/>
      </geometry>
      <material name="">
        <color rgba="0.6 0.8 0.1 1"/>
      </material>
    </visual>
  </link>
  <joint name="imu_joint_1" type="fixed">
    <parent link="base_link"/>
    <child link="imu_link_1"/>
    <origin rpy="0.0 0.0 0.0" xyz="0.0 0.0 0.005"/>
  </joint>
  <gazebo>
    <plugin filename="libhector_gazebo_ros_imu.so" name="imu_1_controller">
      <updateRate>100</updateRate>
      <bodyName>imu_link_1</bodyName>
      <topicName>sensors/imu_1</topicName>
      <accelDrift>0.005 0.005 0.005</accelDrift>
      <accelGaussianNoise>0.005 0.005 0.005</accelGaussianNoise>
      <rateDrift>0.005 0.005 0.005 </rateDrift>
      <rateGaussianNoise>0.005 0.005 0.005</rateGaussianNoise>
      <headingDrift>0.005</headingDrift>
      <headingGaussianNoise>0.005</headingGaussianNoise>
    </plugin>
    <material>Gazebo/Yellow</material>
  </gazebo>
  <!-- VL53L0X ToF sensor-->
  <link name="tof_link_1">
    <inertial>
      <mass value="0.001"/>
      <origin xyz="0 0 0"/>
      <inertia ixx="1e-09" ixy="0" ixz="0" iyy="1e-09" iyz="0" izz="1e-09"/>
    </inertial>
    <visual>
      <origin rpy="0 0 0" xyz="0 0 0"/>
      <geometry>
        <box size="0.005 0.015 0.005"/>
      </geometry>
      <material name="Red">
        <color rgba="1 0.2 0.2 1"/>
      </material>
    </visual>
  </link>
  <joint name="tof_joint_1" type="fixed">
    <origin rpy="0.0 1.57 0.0" xyz="0.15 0.0 -0.025"/>
    <!-- <origin xyz="0 0 -0.029" rpy="0 1.57 0"/> -->
    <parent link="base_link"/>
    <child link="tof_link_1"/>
  </joint>
  <gazebo reference="tof_link_1">
    <sensor name="tof_sensor_1" type="ray">
      <visualize>true</visualize>
      <update_rate>20</update_rate>
      <always_on>1</always_on>
      <ray>
        <scan>
          <horizontal>
            <samples>10</samples>
            <resolution>1</resolution>
            <min_angle>-0.02618</min_angle>
            <max_angle>0.02618</max_angle>
          </horizontal>
          <vertical>
            <samples>10</samples>
            <resolution>1</resolution>
            <min_angle>-0.02618</min_angle>
            <max_angle>0.02618</max_angle>
          </vertical>
        </scan>
        <range>
          <min>0.002</min>
          <max>2</max>
          <resolution>0.005</resolution>
        </range>
      </ray>
      <plugin filename="libgazebo_ros_range.so" name="tof_plugin_1">
        <topicName>sensors/range_tof_1</topicName>
        <frameName>frame_range_tof_1</frameName>
        <gaussianNoise>0.005</gaussianNoise>
        <updateRate>20</updateRate>
        <radiation>light</radiation>
        <fov>0.43</fov>
      </plugin>
    </sensor>
    <material>Gazebo/Red</material>
  </gazebo>
  <!-- VL53L0X ToF sensor-->
  <link name="tof_link_2">
    <inertial>
      <mass value="0.001"/>
      <origin xyz="0 0 0"/>
      <inertia ixx="1e-09" ixy="0" ixz="0" iyy="1e-09" iyz="0" izz="1e-09"/>
    </inertial>
    <visual>
      <origin rpy="0 0 0" xyz="0 0 0"/>
      <geometry>
        <box size="0.005 0.015 0.005"/>
      </geometry>
      <material name="Red">
        <color rgba="1 0.2 0.2 1"/>
      </material>
    </visual>
  </link>
  <joint name="tof_joint_2" type="fixed">
    <origin rpy="0.0 1.57 0.0" xyz="0.065 0.047 -0.025"/>
    <!-- <origin xyz="0 0 -0.029" rpy="0 1.57 0"/> -->
    <parent link="base_link"/>
    <child link="tof_link_2"/>
  </joint>
  <gazebo reference="tof_link_2">
    <sensor name="tof_sensor_2" type="ray">
      <visualize>true</visualize>
      <update_rate>20</update_rate>
      <always_on>1</always_on>
      <ray>
        <scan>
          <horizontal>
            <samples>10</samples>
            <resolution>1</resolution>
            <min_angle>-0.02618</min_angle>
            <max_angle>0.02618</max_angle>
          </horizontal>
          <vertical>
            <samples>10</samples>
            <resolution>1</resolution>
            <min_angle>-0.02618</min_angle>
            <max_angle>0.02618</max_angle>
          </vertical>
        </scan>
        <range>
          <min>0.002</min>
          <max>2</max>
          <resolution>0.005</resolution>
        </range>
      </ray>
      <plugin filename="libgazebo_ros_range.so" name="tof_plugin_2">
        <topicName>sensors/range_tof_2</topicName>
        <frameName>frame_range_tof_2</frameName>
        <gaussianNoise>0.005</gaussianNoise>
        <updateRate>20</updateRate>
        <radiation>light</radiation>
        <fov>0.43</fov>
      </plugin>
    </sensor>
    <material>Gazebo/Red</material>
  </gazebo>
  <!-- VL53L0X ToF sensor-->
  <link name="tof_link_6">
    <inertial>
      <mass value="0.001"/>
      <origin xyz="0 0 0"/>
      <inertia ixx="1e-09" ixy="0" ixz="0" iyy="1e-09" iyz="0" izz="1e-09"/>
    </inertial>
    <visual>
      <origin rpy="0 0 0" xyz="0 0 0"/>
      <geometry>
        <box size="0.005 0.015 0.005"/>
      </geometry>
      <material name="Red">
        <color rgba="1 0.2 0.2 1"/>
      </material>
    </visual>
  </link>
  <joint name="tof_joint_6" type="fixed">
    <origin rpy="0.0 1.57 0.0" xyz="0.065 -0.047 -0.025"/>
    <!-- <origin xyz="0 0 -0.029" rpy="0 1.57 0"/> -->
    <parent link="base_link"/>
    <child link="tof_link_6"/>
  </joint>
  <gazebo reference="tof_link_6">
    <sensor name="tof_sensor_6" type="ray">
      <visualize>true</visualize>
      <update_rate>20</update_rate>
      <always_on>1</always_on>
      <ray>
        <scan>
          <horizontal>
            <samples>10</samples>
            <resolution>1</resolution>
            <min_angle>-0.02618</min_angle>
            <max_angle>0.02618</max_angle>
          </horizontal>
          <vertical>
            <samples>10</samples>
            <resolution>1</resolution>
            <min_angle>-0.02618</min_angle>
            <max_angle>0.02618</max_angle>
          </vertical>
        </scan>
        <range>
          <min>0.002</min>
          <max>2</max>
          <resolution>0.005</resolution>
        </range>
      </ray>
      <plugin filename="libgazebo_ros_range.so" name="tof_plugin_6">
        <topicName>sensors/range_tof_6</topicName>
        <frameName>frame_range_tof_6</frameName>
        <gaussianNoise>0.005</gaussianNoise>
        <updateRate>20</updateRate>
        <radiation>light</radiation>
        <fov>0.43</fov>
      </plugin>
    </sensor>
    <material>Gazebo/Red</material>
  </gazebo>
  <!-- VL53L0X ToF sensor-->
  <link name="tof_link_4">
    <inertial>
      <mass value="0.001"/>
      <origin xyz="0 0 0"/>
      <inertia ixx="1e-09" ixy="0" ixz="0" iyy="1e-09" iyz="0" izz="1e-09"/>
    </inertial>
    <visual>
      <origin rpy="0 0 0" xyz="0 0 0"/>
      <geometry>
        <box size="0.005 0.015 0.005"/>
      </geometry>
      <material name="Red">
        <color rgba="1 0.2 0.2 1"/>
      </material>
    </visual>
  </link>
  <joint name="tof_joint_4" type="fixed">
    <origin rpy="0.0 1.57 0.0" xyz="-0.15 0.0 -0.025"/>
    <!-- <origin xyz="0 0 -0.029" rpy="0 1.57 0"/> -->
    <parent link="base_link"/>
    <child link="tof_link_4"/>
  </joint>
  <gazebo reference="tof_link_4">
    <sensor name="tof_sensor_4" type="ray">
      <visualize>true</visualize>
      <update_rate>20</update_rate>
      <always_on>1</always_on>
      <ray>
        <scan>
          <horizontal>
            <samples>10</samples>
            <resolution>1</resolution>
            <min_angle>-0.02618</min_angle>
            <max_angle>0.02618</max_angle>
          </horizontal>
          <vertical>
            <samples>10</samples>
            <resolution>1</resolution>
            <min_angle>-0.02618</min_angle>
            <max_angle>0.02618</max_angle>
          </vertical>
        </scan>
        <range>
          <min>0.002</min>
          <max>2</max>
          <resolution>0.005</resolution>
        </range>
      </ray>
      <plugin filename="libgazebo_ros_range.so" name="tof_plugin_4">
        <topicName>sensors/range_tof_4</topicName>
        <frameName>frame_range_tof_4</frameName>
        <gaussianNoise>0.005</gaussianNoise>
        <updateRate>20</updateRate>
        <radiation>light</radiation>
        <fov>0.43</fov>
      </plugin>
    </sensor>
    <material>Gazebo/Red</material>
  </gazebo>
  <!-- VL53L0X ToF sensor-->
  <link name="tof_link_3">
    <inertial>
      <mass value="0.001"/>
      <origin xyz="0 0 0"/>
      <inertia ixx="1e-09" ixy="0" ixz="0" iyy="1e-09" iyz="0" izz="1e-09"/>
    </inertial>
    <visual>
      <origin rpy="0 0 0" xyz="0 0 0"/>
      <geometry>
        <box size="0.005 0.015 0.005"/>
      </geometry>
      <material name="Red">
        <color rgba="1 0.2 0.2 1"/>
      </material>
    </visual>
  </link>
  <joint name="tof_joint_3" type="fixed">
    <origin rpy="0.0 1.57 0.0" xyz="-0.065 0.047 -0.025"/>
    <!-- <origin xyz="0 0 -0.029" rpy="0 1.57 0"/> -->
    <parent link="base_link"/>
    <child link="tof_link_3"/>
  </joint>
  <gazebo reference="tof_link_3">
    <sensor name="tof_sensor_3" type="ray">
      <visualize>true</visualize>
      <update_rate>20</update_rate>
      <always_on>1</always_on>
      <ray>
        <scan>
          <horizontal>
            <samples>10</samples>
            <resolution>1</resolution>
            <min_angle>-0.02618</min_angle>
            <max_angle>0.02618</max_angle>
          </horizontal>
          <vertical>
            <samples>10</samples>
            <resolution>1</resolution>
            <min_angle>-0.02618</min_angle>
            <max_angle>0.02618</max_angle>
          </vertical>
        </scan>
        <range>
          <min>0.002</min>
          <max>2</max>
          <resolution>0.005</resolution>
        </range>
      </ray>
      <plugin filename="libgazebo_ros_range.so" name="tof_plugin_3">
        <topicName>sensors/range_tof_3</topicName>
        <frameName>frame_range_tof_3</frameName>
        <gaussianNoise>0.005</gaussianNoise>
        <updateRate>20</updateRate>
        <radiation>light</radiation>
        <fov>0.43</fov>
      </plugin>
    </sensor>
    <material>Gazebo/Red</material>
  </gazebo>
  <!-- VL53L0X ToF sensor-->
  <link name="tof_link_5">
    <inertial>
      <mass value="0.001"/>
      <origin xyz="0 0 0"/>
      <inertia ixx="1e-09" ixy="0" ixz="0" iyy="1e-09" iyz="0" izz="1e-09"/>
    </inertial>
    <visual>
      <origin rpy="0 0 0" xyz="0 0 0"/>
      <geometry>
        <box size="0.005 0.015 0.005"/>
      </geometry>
      <material name="Red">
        <color rgba="1 0.2 0.2 1"/>
      </material>
    </visual>
  </link>
  <joint name="tof_joint_5" type="fixed">
    <origin rpy="0.0 1.57 0.0" xyz="-0.065 -0.047 -0.025"/>
    <!-- <origin xyz="0 0 -0.029" rpy="0 1.57 0"/> -->
    <parent link="base_link"/>
    <child link="tof_link_5"/>
  </joint>
  <gazebo reference="tof_link_5">
    <sensor name="tof_sensor_5" type="ray">
      <visualize>true</visualize>
      <update_rate>20</update_rate>
      <always_on>1</always_on>
      <ray>
        <scan>
          <horizontal>
            <samples>10</samples>
            <resolution>1</resolution>
            <min_angle>-0.02618</min_angle>
            <max_angle>0.02618</max_angle>
          </horizontal>
          <vertical>
            <samples>10</samples>
            <resolution>1</resolution>
            <min_angle>-0.02618</min_angle>
            <max_angle>0.02618</max_angle>
          </vertical>
        </scan>
        <range>
          <min>0.002</min>
          <max>2</max>
          <resolution>0.005</resolution>
        </range>
      </ray>
      <plugin filename="libgazebo_ros_range.so" name="tof_plugin_5">
        <topicName>sensors/range_tof_5</topicName>
        <frameName>frame_range_tof_5</frameName>
        <gaussianNoise>0.005</gaussianNoise>
        <updateRate>20</updateRate>
        <radiation>light</radiation>
        <fov>0.43</fov>
      </plugin>
    </sensor>
    <material>Gazebo/Red</material>
  </gazebo>
  <gazebo reference="fl_shank_link">
    <sensor name="fl_link_contact_sensor" type="contact">
      <contact>
        <collision>fl_shank_link_collision</collision>
      </contact>
      <plugin filename="libgazebo_ros_bumper.so" name="gazebo_ros_bumper_controller">
        <bumperTopicName>fl_contact</bumperTopicName>
        <frameName>fl_shank_link</frameName>
      </plugin>
    </sensor>
  </gazebo>
  <gazebo reference="fr_shank_link">
    <sensor name="fr_link_contact_sensor" type="contact">
      <contact>
        <collision>fr_shank_link_collision</collision>
      </contact>
      <plugin filename="libgazebo_ros_bumper.so" name="gazebo_ros_bumper_controller">
        <bumperTopicName>fr_contact</bumperTopicName>
        <frameName>fr_shank_link</frameName>
      </plugin>
    </sensor>
  </gazebo>
  <gazebo reference="bl_shank_link">
    <sensor name="bl_link_contact_sensor" type="contact">
      <contact>
        <collision>bl_shank_link_collision</collision>
      </contact>
      <plugin filename="libgazebo_ros_bumper.so" name="gazebo_ros_bumper_controller">
        <bumperTopicName>bl_contact</bumperTopicName>
        <frameName>bl_shank_link</frameName>
      </plugin>
    </sensor>
  </gazebo>
  <gazebo reference="br_shank_link">
    <sensor name="br_link_contact_sensor" type="contact">
      <contact>
        <collision>br_shank_link_collision</collision>
      </contact>
      <plugin filename="libgazebo_ros_bumper.so" name="gazebo_ros_bumper_controller">
        <bumperTopicName>br_contact</bumperTopicName>
        <frameName>br_shank_link</frameName>
      </plugin>
    </sensor>
  </gazebo>
</robot>

